Workbook

Sheet RESUMEN
E2: TOTAL GLOBAL JULIO/AGOSTO | G2: TOTAL GLOBAL RACIONES JULIO/AGOSTO
E3: =K9 -> 29697840 | G3: =J9 -> 945908
B6: 46266
B7: 1a. Semana de septiembre y período de agosto pendiente de liquidar (RACIONES SERVIDAS) | D7: 2a. Semana (RACIONES SERVIDAS) | F7: 3a. Semana (RACIONES SERVIDAS) | H7: 4a. Semana (RACIONES SERVIDAS) | J7: TOTAL GLOBAL
B8: Cantidad de raciones servidas | C8: Ejecución Financiera | D8: Cantidad de raciones servidas | E8: Ejecución Financiera | F8: Cantidad de racione servidas | G8: Ejecución Financiera | H8: Cantidad de racione servidas | I8: Ejecución Financiera | J8: Acumulado Raciones | K8: Acumulado Ejecución
B9: =SEPTIEMBRE!O185+SEPTIEMBRE!U185 -> 431352 | C9: =SEPTIEMBRE!R185+SEPTIEMBRE!X185 -> 13503433 | D9: =SEPTIEMBRE!AA185 -> 143697 | E9: =SEPTIEMBRE!AD185 -> 4503499.5 | F9: =SEPTIEMBRE!AG185 -> 233164 | G9: =SEPTIEMBRE!AJ185 -> 7343504.3 | H9: =SEPTIEMBRE!AM185 -> 137695 | I9: =SEPTIEMBRE!AP185 -> 4347402.8 | J9: =B9+D9+F9+H9 -> 945908 | K9: =C9+E9+G9+I9 -> 29697840

Sheet SEPTIEMBRE
E2: CONTRATO ABIERTO, LICITACIÓN Y COMPRA DIRECTA
D3: EJECUCIÓN SEPTIEMBRE 2026
E4: Nuevas Aperturas
E5: suspendidos
E6: Comedores con Corte anticipado | H6: Resaltados en rojo marcan incumplimiento
AQ7: Resumen septiembre 2026 (del 01 al 30 de septiembre 2026
M8: (pendiente de liquidar de agosto) | S8: PRIMERA SEMANA (del 1 al 11 de Septiembre) | Y8: SEGUNDA SEMANA (del 14 al 18 de septiembre) | AE8: TERCERA SEMANA (del 21 al 25 de septiembre) | AK8: CUARTA SEMANA (del 28 al 30 de septiembre) | AQ8: TOTAL RACIONES SERVIDAS | AT8: EJECUCIÓN FINANCIERA GLOBAL
A9: No. | B9: DEPARTAMENTO | C9: MUNICIPIO | D9: COMEDOR SOCIAL | E9: MODALIDAD | F9: DESAYUNO | G9: ALMUERZO | H9: DESAYUNO | I9: ALMUERZO | J9: MODALIDAD DE CONTRATACION | K9: REGION O LOTE | L9: PROVEEDOR | M9: DESAYUNO | N9: ALMUERZO | O9: TOTAL | P9: DESAYUNO | Q9: ALMUERZO | R9: TOTAL | S9: DESAYUNO | T9: ALMUERZO | U9: TOTAL | V9: DESAYUNO | W9: ALMUERZO | X9: TOTAL | Y9: DESAYUNO | Z9: ALMUERZO | AA9: TOTAL | AB9: DESAYUNO | AC9: ALMUERZO | AD9: TOTAL | AE9: DESAYUNO | AF9: ALMUERZO | AG9: TOTAL | AH9: DESAYUNO | AI9: ALMUERZO | AJ9: TOTAL | AK9: DESAYUNO | AL9: ALMUERZO | AM9: TOTAL | AN9: DESAYUNO | AO9: ALMUERZO | AP9: TOTAL | AQ9: DESAYUNO | AR9: ALMUERZO | AS9: TOTAL | AT9: DESAYUNO | AU9: ALMUERZO | AV9: TOTAL
A10: 1 | B10: ALTA VERAPAZ | C10: CAHABÓN | D10: CAHABÓN | E10: FIJO | F10: 130 | G10: 200 | H10: 31.27 | I10: 34.45 | J10: CONTRATO ABIERTO | L10: BANQUETES DE GUATEMALA, S.A. | O10: =M10+N10 -> 0 | P10: =M10*H10 -> 0 | Q10: =N10*I10 -> 0 | R10: =P10+Q10 -> 0 | S10: 1040 | T10: 1800 | U10: =S10+T10 -> 2840 | V10: =S10*H10 -> 32520.8 | W10: =T10*I10 -> 62010 | X10: =V10+W10 -> 94530.8 | Y10: 390 | Z10: 600 | AA10: =Y10+Z10 -> 990 | AB10: =Y10*H10 -> 12195.3 | AC10: =Z10*I10 -> 20670 | AD10: =AB10+AC10 -> 32865.3 | AE10: 650 | AF10: 1000 | AG10: =AE10+AF10 -> 1650 | AH10: =AE10*H10 -> 20325.5 | AI10: =AF10*I10 -> 34450 | AJ10: =AH10+AI10 -> 54775.5 | AK10: 390 | AL10: 600 | AM10: =AK10+AL10 -> 990 | AN10: =AK10*H10 -> 12195.3 | AO10: =AL10*I10 -> 20670 | AP10: =AN10+AO10 -> 32865.3 | AQ10: =S10+Y10+AE10+AK10+M10 -> 2470 | AR10: =T10+Z10+AF10+AL10+N10 -> 4000 | AS10: =AQ10+AR10 -> 6470 | AT10: =V10+AB10+AH10+AN10+P10 -> 77236.9 | AU10: =W10+AC10+AI10+AO10+Q10 -> 137800 | AV10: =AT10+AU10 -> 215036.9 | AX10: =X10+AD10+AJ10+AP10+R10 -> 215036.9
A11: 2 | B11: ALTA VERAPAZ | C11: CHAHAL | D11: CHAHAL | E11: FIJO | F11: 150 | G11: 225 | H11: 31.27 | I11: 34.45 | J11: CONTRATO ABIERTO | L11: BANQUETES DE GUATEMALA, S.A. | O11: =M11+N11 -> 0 | P11: =M11*H11 -> 0 | Q11: =N11*I11 -> 0 | R11: =P11+Q11 -> 0 | S11: 1350 | T11: 2025 | U11: =S11+T11 -> 3375 | V11: =S11*H11 -> 42214.5 | W11: =T11*I11 -> 69761.25 | X11: =V11+W11 -> 111975.75 | Y11: 450 | Z11: 675 | AA11: =Y11+Z11 -> 1125 | AB11: =Y11*H11 -> 14071.5 | AC11: =Z11*I11 -> 23253.75 | AD11: =AB11+AC11 -> 37325.25 | AE11: 750 | AF11: 1125 | AG11: =AE11+AF11 -> 1875 | AH11: =AE11*H11 -> 23452.5 | AI11: =AF11*I11 -> 38756.25 | AJ11: =AH11+AI11 -> 62208.75 | AK11: 450 | AL11: 675 | AM11: =AK11+AL11 -> 1125 | AN11: =AK11*H11 -> 14071.5 | AO11: =AL11*I11 -> 23253.75 | AP11: =AN11+AO11 -> 37325.25 | AQ11: =S11+Y11+AE11+AK11+M11 -> 3000 | AR11: =T11+Z11+AF11+AL11+N11 -> 4500 | AS11: =AQ11+AR11 -> 7500 | AT11: =V11+AB11+AH11+AN11+P11 -> 93810 | AU11: =W11+AC11+AI11+AO11+Q11 -> 155025 | AV11: =AT11+AU11 -> 248835 | AX11: =X11+AD11+AJ11+AP11+R11 -> 248835
A12: 3 | B12: ALTA VERAPAZ | C12: CHISEC | D12: CHISEC | E12: FIJO | F12: 100 | G12: 150 | H12: 31.27 | I12: 34.45 | J12: CONTRATO ABIERTO | L12: BANQUETES DE GUATEMALA, S.A. | O12: =M12+N12 -> 0 | P12: =M12*H12 -> 0 | Q12: =N12*I12 -> 0 | R12: =P12+Q12 -> 0 | S12: 900 | T12: 1350 | U12: =S12+T12 -> 2250 | V12: =S12*H12 -> 28143 | W12: =T12*I12 -> 46507.5 | X12: =V12+W12 -> 74650.5 | Y12: 300 | Z12: 450 | AA12: =Y12+Z12 -> 750 | AB12: =Y12*H12 -> 9381 | AC12: =Z12*I12 -> 15502.5 | AD12: =AB12+AC12 -> 24883.5 | AE12: 500 | AF12: 750 | AG12: =AE12+AF12 -> 1250 | AH12: =AE12*H12 -> 15635 | AI12: =AF12*I12 -> 25837.5 | AJ12: =AH12+AI12 -> 41472.5 | AK12: 300 | AL12: 450 | AM12: =AK12+AL12 -> 750 | AN12: =AK12*H12 -> 9381 | AO12: =AL12*I12 -> 15502.5 | AP12: =AN12+AO12 -> 24883.5 | AQ12: =S12+Y12+AE12+AK12+M12 -> 2000 | AR12: =T12+Z12+AF12+AL12+N12 -> 3000 | AS12: =AQ12+AR12 -> 5000 | AT12: =V12+AB12+AH12+AN12+P12 -> 62540 | AU12: =W12+AC12+AI12+AO12+Q12 -> 103350 | AV12: =AT12+AU12 -> 165890 | AX12: =X12+AD12+AJ12+AP12+R12 -> 165890
A13: 4 | B13: ALTA VERAPAZ | C13: COBÁN | D13: COBÁN | E13: FIJO | F13: 150 | G13: 200 | H13: 23 | I13: 27 | J13: LICITACION | K13: LOTE 4 | L13: PROVEEDORA DE ALIMENTOS EL ROSARIO | O13: =M13+N13 -> 0 | P13: =M13*H13 -> 0 | Q13: =N13*I13 -> 0 | R13: =P13+Q13 -> 0 | S13: 1350 | T13: 1800 | U13: =S13+T13 -> 3150 | V13: =S13*H13 -> 31050 | W13: =T13*I13 -> 48600 | X13: =V13+W13 -> 79650 | Y13: 450 | Z13: 600 | AA13: =Y13+Z13 -> 1050 | AB13: =Y13*H13 -> 10350 | AC13: =Z13*I13 -> 16200 | AD13: =AB13+AC13 -> 26550 | AE13: 750 | AF13: 1000 | AG13: =AE13+AF13 -> 1750 | AH13: =AE13*H13 -> 17250 | AI13: =AF13*I13 -> 27000 | AJ13: =AH13+AI13 -> 44250 | AK13: 450 | AL13: 600 | AM13: =AK13+AL13 -> 1050 | AN13: =AK13*H13 -> 10350 | AO13: =AL13*I13 -> 16200 | AP13: =AN13+AO13 -> 26550 | AQ13: =S13+Y13+AE13+AK13+M13 -> 3000 | AR13: =T13+Z13+AF13+AL13+N13 -> 4000 | AS13: =AQ13+AR13 -> 7000 | AT13: =V13+AB13+AH13+AN13+P13 -> 69000 | AU13: =W13+AC13+AI13+AO13+Q13 -> 108000 | AV13: =AT13+AU13 -> 177000 | AX13: =X13+AD13+AJ13+AP13+R13 -> 177000
A14: 5 | B14: ALTA VERAPAZ | C14: FRAY BARTOLOMÉ DE LAS CASAS | D14: FRAY BARTOLOMÉ DE LAS CASAS | E14: FIJO | F14: 150 | G14: 250 | H14: 24 | I14: 28 | J14: LICITACION | K14: LOTE 5 | L14: PROVEEDORA DE ALIMENTOS EL ROSARIO | O14: =M14+N14 -> 0 | P14: =M14*H14 -> 0 | Q14: =N14*I14 -> 0 | R14: =P14+Q14 -> 0 | S14: 1305 | T14: 2211 | U14: =S14+T14 -> 3516 | V14: =S14*H14 -> 31320 | W14: =T14*I14 -> 61908 | X14: =V14+W14 -> 93228 | Y14: 450 | Z14: 750 | AA14: =Y14+Z14 -> 1200 | AB14: =Y14*H14 -> 10800 | AC14: =Z14*I14 -> 21000 | AD14: =AB14+AC14 -> 31800 | AE14: 750 | AF14: 1200 | AG14: =AE14+AF14 -> 1950 | AH14: =AE14*H14 -> 18000 | AI14: =AF14*I14 -> 33600 | AJ14: =AH14+AI14 -> 51600 | AK14: 450 | AL14: 750 | AM14: =AK14+AL14 -> 1200 | AN14: =AK14*H14 -> 10800 | AO14: =AL14*I14 -> 21000 | AP14: =AN14+AO14 -> 31800 | AQ14: =S14+Y14+AE14+AK14+M14 -> 2955 | AR14: =T14+Z14+AF14+AL14+N14 -> 4911 | AS14: =AQ14+AR14 -> 7866 | AT14: =V14+AB14+AH14+AN14+P14 -> 70920 | AU14: =W14+AC14+AI14+AO14+Q14 -> 137508 | AV14: =AT14+AU14 -> 208428 | AX14: =X14+AD14+AJ14+AP14+R14 -> 208428
A15: 6 | B15: ALTA VERAPAZ | C15: PANZÓS | D15: PANZÓS | E15: FIJO | F15: 150 | G15: 250 | H15: 23 | I15: 27 | J15: LICITACION | K15: LOTE 6 | L15: PROVEEDORA DE ALIMENTOS EL ROSARIO | O15: =M15+N15 -> 0 | P15: =M15*H15 -> 0 | Q15: =N15*I15 -> 0 | R15: =P15+Q15 -> 0 | S15: 1350 | T15: 2250 | U15: =S15+T15 -> 3600 | V15: =S15*H15 -> 31050 | W15: =T15*I15 -> 60750 | X15: =V15+W15 -> 91800 | Y15: 450 | Z15: 750 | AA15: =Y15+Z15 -> 1200 | AB15: =Y15*H15 -> 10350 | AC15: =Z15*I15 -> 20250 | AD15: =AB15+AC15 -> 30600 | AE15: 750 | AF15: 1240 | AG15: =AE15+AF15 -> 1990 | AH15: =AE15*H15 -> 17250 | AI15: =AF15*I15 -> 33480 | AJ15: =AH15+AI15 -> 50730 | AK15: 450 | AL15: 750 | AM15: =AK15+AL15 -> 1200 | AN15: =AK15*H15 -> 10350 | AO15: =AL15*I15 -> 20250 | AP15: =AN15+AO15 -> 30600 | AQ15: =S15+Y15+AE15+AK15+M15 -> 3000 | AR15: =T15+Z15+AF15+AL15+N15 -> 4990 | AS15: =AQ15+AR15 -> 7990 | AT15: =V15+AB15+AH15+AN15+P15 -> 69000 | AU15: =W15+AC15+AI15+AO15+Q15 -> 134730 | AV15: =AT15+AU15 -> 203730 | AX15: =X15+AD15+AJ15+AP15+R15 -> 203730
A16: 7 | B16: ALTA VERAPAZ | C16: RAXRUHÁ | D16: RAXRUHÁ | E16: FIJO | F16: 100 | G16: 150 | H16: 31.27 | I16: 34.45 | J16: CONTRATO ABIERTO | L16: BANQUETES DE GUATEMALA, S.A. | O16: =M16+N16 -> 0 | P16: =M16*H16 -> 0 | Q16: =N16*I16 -> 0 | R16: =P16+Q16 -> 0 | S16: 900 | T16: 1350 | U16: =S16+T16 -> 2250 | V16: =S16*H16 -> 28143 | W16: =T16*I16 -> 46507.5 | X16: =V16+W16 -> 74650.5 | Y16: 300 | Z16: 450 | AA16: =Y16+Z16 -> 750 | AB16: =Y16*H16 -> 9381 | AC16: =Z16*I16 -> 15502.5 | AD16: =AB16+AC16 -> 24883.5 | AE16: 500 | AF16: 750 | AG16: =AE16+AF16 -> 1250 | AH16: =AE16*H16 -> 15635 | AI16: =AF16*I16 -> 25837.5 | AJ16: =AH16+AI16 -> 41472.5 | AK16: 300 | AL16: 450 | AM16: =AK16+AL16 -> 750 | AN16: =AK16*H16 -> 9381 | AO16: =AL16*I16 -> 15502.5 | AP16: =AN16+AO16 -> 24883.5 | AQ16: =S16+Y16+AE16+AK16+M16 -> 2000 | AR16: =T16+Z16+AF16+AL16+N16 -> 3000 | AS16: =AQ16+AR16 -> 5000 | AT16: =V16+AB16+AH16+AN16+P16 -> 62540 | AU16: =W16+AC16+AI16+AO16+Q16 -> 103350 | AV16: =AT16+AU16 -> 165890 | AX16: =X16+AD16+AJ16+AP16+R16 -> 165890
A17: 8 | B17: ALTA VERAPAZ | C17: SAN AGUSTÍN LANQUÍN | D17: SAN AGUSTÍN LANQUÍN | E17: MÓVIL | F17: 150 | G17: 250 | H17: 31.27 | I17: 34.45 | J17: CONTRATO ABIERTO | L17: BANQUETES DE GUATEMALA, S.A. | O17: =M17+N17 -> 0 | P17: =M17*H17 -> 0 | Q17: =N17*I17 -> 0 | R17: =P17+Q17 -> 0 | S17: 1313 | T17: 2249 | U17: =S17+T17 -> 3562 | V17: =S17*H17 -> 41057.51 | W17: =T17*I17 -> 77478.05 | X17: =V17+W17 -> 118535.56 | Y17: 450 | Z17: 705 | AA17: =Y17+Z17 -> 1155 | AB17: =Y17*H17 -> 14071.5 | AC17: =Z17*I17 -> 24287.25 | AD17: =AB17+AC17 -> 38358.75 | AE17: 750 | AF17: 1210 | AG17: =AE17+AF17 -> 1960 | AH17: =AE17*H17 -> 23452.5 | AI17: =AF17*I17 -> 41684.5 | AJ17: =AH17+AI17 -> 65137 | AK17: 450 | AL17: 750 | AM17: =AK17+AL17 -> 1200 | AN17: =AK17*H17 -> 14071.5 | AO17: =AL17*I17 -> 25837.5 | AP17: =AN17+AO17 -> 39909 | AQ17: =S17+Y17+AE17+AK17+M17 -> 2963 | AR17: =T17+Z17+AF17+AL17+N17 -> 4914 | AS17: =AQ17+AR17 -> 7877 | AT17: =V17+AB17+AH17+AN17+P17 -> 92653.01 | AU17: =W17+AC17+AI17+AO17+Q17 -> 169287.3 | AV17: =AT17+AU17 -> 261940.31 | AX17: =X17+AD17+AJ17+AP17+R17 -> 261940.31
A18: 9 | B18: ALTA VERAPAZ | C18: SAN CRISTÓBAL VERAPAZ | D18: SAN CRISTÓBAL VERAPAZ | E18: FIJO | F18: 100 | G18: 150 | H18: 31.27 | I18: 34.45 | J18: CONTRATO ABIERTO | L18: BANQUETES DE GUATEMALA, S.A. | O18: =M18+N18 -> 0 | P18: =M18*H18 -> 0 | Q18: =N18*I18 -> 0 | R18: =P18+Q18 -> 0 | S18: 900 | T18: 1350 | U18: =S18+T18 -> 2250 | V18: =S18*H18 -> 28143 | W18: =T18*I18 -> 46507.5 | X18: =V18+W18 -> 74650.5 | Y18: 300 | Z18: 450 | AA18: =Y18+Z18 -> 750 | AB18: =Y18*H18 -> 9381 | AC18: =Z18*I18 -> 15502.5 | AD18: =AB18+AC18 -> 24883.5 | AE18: 500 | AF18: 750 | AG18: =AE18+AF18 -> 1250 | AH18: =AE18*H18 -> 15635 | AI18: =AF18*I18 -> 25837.5 | AJ18: =AH18+AI18 -> 41472.5 | AK18: 300 | AL18: 450 | AM18: =AK18+AL18 -> 750 | AN18: =AK18*H18 -> 9381 | AO18: =AL18*I18 -> 15502.5 | AP18: =AN18+AO18 -> 24883.5 | AQ18: =S18+Y18+AE18+AK18+M18 -> 2000 | AR18: =T18+Z18+AF18+AL18+N18 -> 3000 | AS18: =AQ18+AR18 -> 5000 | AT18: =V18+AB18+AH18+AN18+P18 -> 62540 | AU18: =W18+AC18+AI18+AO18+Q18 -> 103350 | AV18: =AT18+AU18 -> 165890 | AX18: =X18+AD18+AJ18+AP18+R18 -> 165890
A19: 10 | B19: ALTA VERAPAZ | C19: SAN JUAN CHAMELCO | D19: SAN JUAN CHAMELCO | E19: FIJO | F19: 100 | G19: 150 | H19: 23 | I19: 27 | J19: LICITACION | K19: LOTE 9 | L19: PROVEEDORA DE ALIMENTOS EL ROSARIO | O19: =M19+N19 -> 0 | P19: =M19*H19 -> 0 | Q19: =N19*I19 -> 0 | R19: =P19+Q19 -> 0 | S19: 900 | T19: 1350 | U19: =S19+T19 -> 2250 | V19: =S19*H19 -> 20700 | W19: =T19*I19 -> 36450 | X19: =V19+W19 -> 57150 | Y19: 300 | Z19: 450 | AA19: =Y19+Z19 -> 750 | AB19: =Y19*H19 -> 6900 | AC19: =Z19*I19 -> 12150 | AD19: =AB19+AC19 -> 19050 | AE19: 500 | AF19: 750 | AG19: =AE19+AF19 -> 1250 | AH19: =AE19*H19 -> 11500 | AI19: =AF19*I19 -> 20250 | AJ19: =AH19+AI19 -> 31750 | AK19: 300 | AL19: 450 | AM19: =AK19+AL19 -> 750 | AN19: =AK19*H19 -> 6900 | AO19: =AL19*I19 -> 12150 | AP19: =AN19+AO19 -> 19050 | AQ19: =S19+Y19+AE19+AK19+M19 -> 2000 | AR19: =T19+Z19+AF19+AL19+N19 -> 3000 | AS19: =AQ19+AR19 -> 5000 | AT19: =V19+AB19+AH19+AN19+P19 -> 46000 | AU19: =W19+AC19+AI19+AO19+Q19 -> 81000 | AV19: =AT19+AU19 -> 127000 | AX19: =X19+AD19+AJ19+AP19+R19 -> 127000
A20: 11 | B20: ALTA VERAPAZ | C20: SAN MIGUEL TUCURÚ | D20: SAN MIGUEL TUCURÚ | E20: FIJO | F20: 75 | G20: 125 | H20: 31.27 | I20: 34.45 | J20: CONTRATO ABIERTO | L20: BANQUETES DE GUATEMALA, S.A. | O20: =M20+N20 -> 0 | P20: =M20*H20 -> 0 | Q20: =N20*I20 -> 0 | R20: =P20+Q20 -> 0 | S20: 675 | T20: 1125 | U20: =S20+T20 -> 1800 | V20: =S20*H20 -> 21107.25 | W20: =T20*I20 -> 38756.25 | X20: =V20+W20 -> 59863.5 | Y20: 225 | Z20: 375 | AA20: =Y20+Z20 -> 600 | AB20: =Y20*H20 -> 7035.75 | AC20: =Z20*I20 -> 12918.75 | AD20: =AB20+AC20 -> 19954.5 | AE20: 225 | AF20: 250 | AG20: =AE20+AF20 -> 475 | AH20: =AE20*H20 -> 7035.75 | AI20: =AF20*I20 -> 8612.5 | AJ20: =AH20+AI20 -> 15648.25 | AK20: 225 | AL20: 375 | AM20: =AK20+AL20 -> 600 | AN20: =AK20*H20 -> 7035.75 | AO20: =AL20*I20 -> 12918.75 | AP20: =AN20+AO20 -> 19954.5 | AQ20: =S20+Y20+AE20+AK20+M20 -> 1350 | AR20: =T20+Z20+AF20+AL20+N20 -> 2125 | AS20: =AQ20+AR20 -> 3475 | AT20: =V20+AB20+AH20+AN20+P20 -> 42214.5 | AU20: =W20+AC20+AI20+AO20+Q20 -> 73206.25 | AV20: =AT20+AU20 -> 115420.75 | AX20: =X20+AD20+AJ20+AP20+R20 -> 115420.75
A21: 12 | B21: ALTA VERAPAZ | C21: SANTA CATALINA LA TINTA | D21: SANTA CATALINA LA TINTA | E21: FIJO | F21: 150 | G21: 250 | H21: 31.27 | I21: 34.45 | J21: CONTRATO ABIERTO | L21: BANQUETES DE GUATEMALA, S.A. | O21: =M21+N21 -> 0 | P21: =M21*H21 -> 0 | Q21: =N21*I21 -> 0 | R21: =P21+Q21 -> 0 | S21: 1302 | T21: 2250 | U21: =S21+T21 -> 3552 | V21: =S21*H21 -> 40713.54 | W21: =T21*I21 -> 77512.5 | X21: =V21+W21 -> 118226.04 | Y21: 430 | Z21: 650 | AA21: =Y21+Z21 -> 1080 | AB21: =Y21*H21 -> 13446.1 | AC21: =Z21*I21 -> 22392.5 | AD21: =AB21+AC21 -> 35838.6 | AE21: 727 | AF21: 877 | AG21: =AE21+AF21 -> 1604 | AH21: =AE21*H21 -> 22733.29 | AI21: =AF21*I21 -> 30212.65 | AJ21: =AH21+AI21 -> 52945.94 | AK21: 450 | AL21: 716 | AM21: =AK21+AL21 -> 1166 | AN21: =AK21*H21 -> 14071.5 | AO21: =AL21*I21 -> 24666.2 | AP21: =AN21+AO21 -> 38737.7 | AQ21: =S21+Y21+AE21+AK21+M21 -> 2909 | AR21: =T21+Z21+AF21+AL21+N21 -> 4493 | AS21: =AQ21+AR21 -> 7402 | AT21: =V21+AB21+AH21+AN21+P21 -> 90964.43 | AU21: =W21+AC21+AI21+AO21+Q21 -> 154783.85 | AV21: =AT21+AU21 -> 245748.28 | AX21: =X21+AD21+AJ21+AP21+R21 -> 245748.28
A22: 13 | B22: ALTA VERAPAZ | C22: SENAHÚ | D22: SENAHÚ | E22: FIJO | F22: 150 | G22: 200 | H22: 23 | I22: 27 | J22: LICITACION | K22: LOTE 12 | L22: PROVEEDORA DE ALIMENTOS EL ROSARIO | O22: =M22+N22 -> 0 | P22: =M22*H22 -> 0 | Q22: =N22*I22 -> 0 | R22: =P22+Q22 -> 0 | S22: 1350 | T22: 1785 | U22: =S22+T22 -> 3135 | V22: =S22*H22 -> 31050 | W22: =T22*I22 -> 48195 | X22: =V22+W22 -> 79245 | Y22: 450 | Z22: 600 | AA22: =Y22+Z22 -> 1050 | AB22: =Y22*H22 -> 10350 | AC22: =Z22*I22 -> 16200 | AD22: =AB22+AC22 -> 26550 | AE22: 750 | AF22: 1000 | AG22: =AE22+AF22 -> 1750 | AH22: =AE22*H22 -> 17250 | AI22: =AF22*I22 -> 27000 | AJ22: =AH22+AI22 -> 44250 | AK22: 450 | AL22: 600 | AM22: =AK22+AL22 -> 1050 | AN22: =AK22*H22 -> 10350 | AO22: =AL22*I22 -> 16200 | AP22: =AN22+AO22 -> 26550 | AQ22: =S22+Y22+AE22+AK22+M22 -> 3000 | AR22: =T22+Z22+AF22+AL22+N22 -> 3985 | AS22: =AQ22+AR22 -> 6985 | AT22: =V22+AB22+AH22+AN22+P22 -> 69000 | AU22: =W22+AC22+AI22+AO22+Q22 -> 107595 | AV22: =AT22+AU22 -> 176595 | AX22: =X22+AD22+AJ22+AP22+R22 -> 176595
A23: 14 | B23: ALTA VERAPAZ | C23: TAMAHÚ | D23: TAMAHÚ | E23: MÓVIL TEMPORAL | F23: 150 | G23: 200 | H23: 31.27 | I23: 34.45 | J23: CONTRATO ABIERTO | L23: BANQUETES DE GUATEMALA, S.A. | O23: =M23+N23 -> 0 | P23: =M23*H23 -> 0 | Q23: =N23*I23 -> 0 | R23: =P23+Q23 -> 0 | S23: 1311 | T23: 1737 | U23: =S23+T23 -> 3048 | V23: =S23*H23 -> 40994.97 | W23: =T23*I23 -> 59839.65 | X23: =V23+W23 -> 100834.62 | Y23: 450 | Z23: 541 | AA23: =Y23+Z23 -> 991 | AB23: =Y23*H23 -> 14071.5 | AC23: =Z23*I23 -> 18637.45 | AD23: =AB23+AC23 -> 32708.95 | AE23: 750 | AF23: 1000 | AG23: =AE23+AF23 -> 1750 | AH23: =AE23*H23 -> 23452.5 | AI23: =AF23*I23 -> 34450 | AJ23: =AH23+AI23 -> 57902.5 | AK23: 450 | AL23: 600 | AM23: =AK23+AL23 -> 1050 | AN23: =AK23*H23 -> 14071.5 | AO23: =AL23*I23 -> 20670 | AP23: =AN23+AO23 -> 34741.5 | AQ23: =S23+Y23+AE23+AK23+M23 -> 2961 | AR23: =T23+Z23+AF23+AL23+N23 -> 3878 | AS23: =AQ23+AR23 -> 6839 | AT23: =V23+AB23+AH23+AN23+P23 -> 92590.47 | AU23: =W23+AC23+AI23+AO23+Q23 -> 133597.1 | AV23: =AT23+AU23 -> 226187.57 | AX23: =X23+AD23+AJ23+AP23+R23 -> 226187.57
A24: 15 | B24: BAJA VERAPAZ | C24: CUBULCO | D24: CUBULCO | E24: FIJO | F24: 100 | G24: 150 | H24: 31.27 | I24: 34.45 | J24: CONTRATO ABIERTO | L24: BANQUETES DE GUATEMALA, S.A. | O24: =M24+N24 -> 0 | P24: =M24*H24 -> 0 | Q24: =N24*I24 -> 0 | R24: =P24+Q24 -> 0 | S24: 542 | T24: 600 | U24: =S24+T24 -> 1142 | V24: =S24*H24 -> 16948.34 | W24: =T24*I24 -> 20670 | X24: =V24+W24 -> 37618.34 | Y24: 300 | Z24: 450 | AA24: =Y24+Z24 -> 750 | AB24: =Y24*H24 -> 9381 | AC24: =Z24*I24 -> 15502.5 | AD24: =AB24+AC24 -> 24883.5 | AE24: 374 | AF24: 750 | AG24: =AE24+AF24 -> 1124 | AH24: =AE24*H24 -> 11694.98 | AI24: =AF24*I24 -> 25837.5 | AJ24: =AH24+AI24 -> 37532.48 | AK24: 300 | AL24: 450 | AM24: =AK24+AL24 -> 750 | AN24: =AK24*H24 -> 9381 | AO24: =AL24*I24 -> 15502.5 | AP24: =AN24+AO24 -> 24883.5 | AQ24: =S24+Y24+AE24+AK24+M24 -> 1516 | AR24: =T24+Z24+AF24+AL24+N24 -> 2250 | AS24: =AQ24+AR24 -> 3766 | AT24: =V24+AB24+AH24+AN24+P24 -> 47405.32 | AU24: =W24+AC24+AI24+AO24+Q24 -> 77512.5 | AV24: =AT24+AU24 -> 124917.82 | AX24: =X24+AD24+AJ24+AP24+R24 -> 124917.82
A25: 16 | B25: BAJA VERAPAZ | C25: CUBULCO | D25: CUBULCO MÓVIL | E25: MÓVIL TEMPORAL | F25: 150 | G25: 200 | H25: 31.27 | I25: 34.45 | J25: CONTRATO ABIERTO | L25: BANQUETES DE GUATEMALA, S.A. | O25: =M25+N25 -> 0 | P25: =M25*H25 -> 0 | Q25: =N25*I25 -> 0 | R25: =P25+Q25 -> 0 | S25: 745 | T25: 800 | U25: =S25+T25 -> 1545 | V25: =S25*H25 -> 23296.15 | W25: =T25*I25 -> 27560 | X25: =V25+W25 -> 50856.15 | Y25: 450 | Z25: 285 | AA25: =Y25+Z25 -> 735 | AB25: =Y25*H25 -> 14071.5 | AC25: =Z25*I25 -> 9818.25 | AD25: =AB25+AC25 -> 23889.75 | AE25: 150 | AF25: 760 | AG25: =AE25+AF25 -> 910 | AH25: =AE25*H25 -> 4690.5 | AI25: =AF25*I25 -> 26182 | AJ25: =AH25+AI25 -> 30872.5 | AK25: 0 | AL25: 400 | AM25: =AK25+AL25 -> 400 | AN25: =AK25*H25 -> 0 | AO25: =AL25*I25 -> 13780 | AP25: =AN25+AO25 -> 13780 | AQ25: =S25+Y25+AE25+AK25+M25 -> 1345 | AR25: =T25+Z25+AF25+AL25+N25 -> 2245 | AS25: =AQ25+AR25 -> 3590 | AT25: =V25+AB25+AH25+AN25+P25 -> 42058.15 | AU25: =W25+AC25+AI25+AO25+Q25 -> 77340.25 | AV25: =AT25+AU25 -> 119398.4 | AX25: =X25+AD25+AJ25+AP25+R25 -> 119398.4
A26: 17 | B26: BAJA VERAPAZ | C26: PURULHÁ | D26: PURULHÁ | E26: FIJO | F26: 100 | G26: 175 | H26: 31.27 | I26: 34.45 | J26: CONTRATO ABIERTO | L26: BANQUETES DE GUATEMALA, S.A. | O26: =M26+N26 -> 0 | P26: =M26*H26 -> 0 | Q26: =N26*I26 -> 0 | R26: =P26+Q26 -> 0 | S26: 900 | T26: 1575 | U26: =S26+T26 -> 2475 | V26: =S26*H26 -> 28143 | W26: =T26*I26 -> 54258.75 | X26: =V26+W26 -> 82401.75 | Y26: 300 | Z26: 567 | AA26: =Y26+Z26 -> 867 | AB26: =Y26*H26 -> 9381 | AC26: =Z26*I26 -> 19533.15 | AD26: =AB26+AC26 -> 28914.15 | AE26: 500 | AF26: 794 | AG26: =AE26+AF26 -> 1294 | AH26: =AE26*H26 -> 15635 | AI26: =AF26*I26 -> 27353.3 | AJ26: =AH26+AI26 -> 42988.3 | AK26: 300 | AL26: 600 | AM26: =AK26+AL26 -> 900 | AN26: =AK26*H26 -> 9381 | AO26: =AL26*I26 -> 20670 | AP26: =AN26+AO26 -> 30051 | AQ26: =S26+Y26+AE26+AK26+M26 -> 2000 | AR26: =T26+Z26+AF26+AL26+N26 -> 3536 | AS26: =AQ26+AR26 -> 5536 | AT26: =V26+AB26+AH26+AN26+P26 -> 62540 | AU26: =W26+AC26+AI26+AO26+Q26 -> 121815.2 | AV26: =AT26+AU26 -> 184355.2 | AX26: =X26+AD26+AJ26+AP26+R26 -> 184355.2
A27: 18 | B27: BAJA VERAPAZ | C27: PURULHÁ | D27: PURULHÁ | E27: MÓVIL | F27: 150 | G27: 250 | H27: 23 | I27: 27 | J27: LICITACION | K27: LOTE 13 | L27: PROVEEDORA DE ALIMENTOS EL ROSARIO | O27: =M27+N27 -> 0 | P27: =M27*H27 -> 0 | Q27: =N27*I27 -> 0 | R27: =P27+Q27 -> 0 | S27: 1324 | T27: 1999 | U27: =S27+T27 -> 3323 | V27: =S27*H27 -> 30452 | W27: =T27*I27 -> 53973 | X27: =V27+W27 -> 84425 | Y27: 450 | Z27: 750 | AA27: =Y27+Z27 -> 1200 | AB27: =Y27*H27 -> 10350 | AC27: =Z27*I27 -> 20250 | AD27: =AB27+AC27 -> 30600 | AE27: 654 | AF27: 865 | AG27: =AE27+AF27 -> 1519 | AH27: =AE27*H27 -> 15042 | AI27: =AF27*I27 -> 23355 | AJ27: =AH27+AI27 -> 38397 | AK27: 450 | AL27: 712 | AM27: =AK27+AL27 -> 1162 | AN27: =AK27*H27 -> 10350 | AO27: =AL27*I27 -> 19224 | AP27: =AN27+AO27 -> 29574 | AQ27: =S27+Y27+AE27+AK27+M27 -> 2878 | AR27: =T27+Z27+AF27+AL27+N27 -> 4326 | AS27: =AQ27+AR27 -> 7204 | AT27: =V27+AB27+AH27+AN27+P27 -> 66194 | AU27: =W27+AC27+AI27+AO27+Q27 -> 116802 | AV27: =AT27+AU27 -> 182996 | AX27: =X27+AD27+AJ27+AP27+R27 -> 182996
A28: 19 | B28: BAJA VERAPAZ | C28: SALAMÁ | D28: SALAMA (CASCO URBANO) | E28: MÓVIL TEMPORAL | F28: 175 | G28: 225 | H28: 28.5 | I28: 29.5 | J28: COMPRA DIRECTA | L28: TECNO SUMINISTROS, S.A. | O28: =M28+N28 -> 0 | P28: =M28*H28 -> 0 | Q28: =N28*I28 -> 0 | R28: =P28+Q28 -> 0 | S28: 1575 | T28: 2025 | U28: =S28+T28 -> 3600 | V28: =S28*H28 -> 44887.5 | W28: =T28*I28 -> 59737.5 | X28: =V28+W28 -> 104625 | Y28: 525 | Z28: 675 | AA28: =Y28+Z28 -> 1200 | AB28: =Y28*H28 -> 14962.5 | AC28: =Z28*I28 -> 19912.5 | AD28: =AB28+AC28 -> 34875 | AE28: 0 | AF28: 0 | AG28: =AE28+AF28 -> 0 | AH28: =AE28*H28 -> 0 | AI28: =AF28*I28 -> 0 | AJ28: =AH28+AI28 -> 0 | AK28: 0 | AL28: 0 | AM28: =AK28+AL28 -> 0 | AN28: =AK28*H28 -> 0 | AO28: =AL28*I28 -> 0 | AP28: =AN28+AO28 -> 0 | AQ28: =S28+Y28+AE28+AK28+M28 -> 2100 | AR28: =T28+Z28+AF28+AL28+N28 -> 2700 | AS28: =AQ28+AR28 -> 4800 | AT28: =V28+AB28+AH28+AN28+P28 -> 59850 | AU28: =W28+AC28+AI28+AO28+Q28 -> 79650 | AV28: =AT28+AU28 -> 139500 | AX28: =X28+AD28+AJ28+AP28+R28 -> 139500
A29: 20 | B29: BAJA VERAPAZ | C29: SALAMA | D29: SALAMA 2 (CHILASCÓ) | E29: MÓVIL TEMPORAL | F29: 200 | G29: 300 | H29: 28.5 | I29: 29.5 | J29: COMPRA DIRECTA | L29: TECNO SUMINISTROS, S.A. | O29: =M29+N29 -> 0 | P29: =M29*H29 -> 0 | Q29: =N29*I29 -> 0 | R29: =P29+Q29 -> 0 | S29: 1800 | T29: 2700 | U29: =S29+T29 -> 4500 | V29: =S29*H29 -> 51300 | W29: =T29*I29 -> 79650 | X29: =V29+W29 -> 130950 | Y29: 600 | Z29: 900 | AA29: =Y29+Z29 -> 1500 | AB29: =Y29*H29 -> 17100 | AC29: =Z29*I29 -> 26550 | AD29: =AB29+AC29 -> 43650 | AE29: 1000 | AF29: 1500 | AG29: =AE29+AF29 -> 2500 | AH29: =AE29*H29 -> 28500 | AI29: =AF29*I29 -> 44250 | AJ29: =AH29+AI29 -> 72750 | AK29: 200 | AL29: 300 | AM29: =AK29+AL29 -> 500 | AN29: =AK29*H29 -> 5700 | AO29: =AL29*I29 -> 8850 | AP29: =AN29+AO29 -> 14550 | AQ29: =S29+Y29+AE29+AK29+M29 -> 3600 | AR29: =T29+Z29+AF29+AL29+N29 -> 5400 | AS29: =AQ29+AR29 -> 9000 | AT29: =V29+AB29+AH29+AN29+P29 -> 102600 | AU29: =W29+AC29+AI29+AO29+Q29 -> 159300 | AV29: =AT29+AU29 -> 261900 | AX29: =X29+AD29+AJ29+AP29+R29 -> 261900
A30: 21 | B30: BAJA VERAPAZ | C30: SAN JERÓNIMO | D30: SAN JERÓNIMO | E30: FIJO | F30: 100 | G30: 200 | H30: 23 | I30: 27 | J30: LICITACION | K30: LOTE 14 | L30: PROVEEDORA DE ALIMENTOS EL ROSARIO | O30: =M30+N30 -> 0 | P30: =M30*H30 -> 0 | Q30: =N30*I30 -> 0 | R30: =P30+Q30 -> 0 | S30: 900 | T30: 1800 | U30: =S30+T30 -> 2700 | V30: =S30*H30 -> 20700 | W30: =T30*I30 -> 48600 | X30: =V30+W30 -> 69300 | Y30: 300 | Z30: 600 | AA30: =Y30+Z30 -> 900 | AB30: =Y30*H30 -> 6900 | AC30: =Z30*I30 -> 16200 | AD30: =AB30+AC30 -> 23100 | AE30: 500 | AF30: 1000 | AG30: =AE30+AF30 -> 1500 | AH30: =AE30*H30 -> 11500 | AI30: =AF30*I30 -> 27000 | AJ30: =AH30+AI30 -> 38500 | AK30: 0 | AL30: 0 | AM30: =AK30+AL30 -> 0 | AN30: =AK30*H30 -> 0 | AO30: =AL30*I30 -> 0 | AP30: =AN30+AO30 -> 0 | AQ30: =S30+Y30+AE30+AK30+M30 -> 1700 | AR30: =T30+Z30+AF30+AL30+N30 -> 3400 | AS30: =AQ30+AR30 -> 5100 | AT30: =V30+AB30+AH30+AN30+P30 -> 39100 | AU30: =W30+AC30+AI30+AO30+Q30 -> 91800 | AV30: =AT30+AU30 -> 130900 | AX30: =X30+AD30+AJ30+AP30+R30 -> 130900
A31: 22 | B31: BAJA VERAPAZ | C31: SAN MIGUEL CHICAJ | D31: SAN MIGUEL CHICAJ | E31: MÓVIL | F31: 150 | G31: 250 | H31: 31.27 | I31: 34.45 | J31: CONTRATO ABIERTO | L31: BANQUETES DE GUATEMALA, S.A. | O31: =M31+N31 -> 0 | P31: =M31*H31 -> 0 | Q31: =N31*I31 -> 0 | R31: =P31+Q31 -> 0 | S31: 900 | T31: 1250 | U31: =S31+T31 -> 2150 | V31: =S31*H31 -> 28143 | W31: =T31*I31 -> 43062.5 | X31: =V31+W31 -> 71205.5 | Y31: 450 | Z31: 750 | AA31: =Y31+Z31 -> 1200 | AB31: =Y31*H31 -> 14071.5 | AC31: =Z31*I31 -> 25837.5 | AD31: =AB31+AC31 -> 39909 | AE31: 750 | AF31: 1250 | AG31: =AE31+AF31 -> 2000 | AH31: =AE31*H31 -> 23452.5 | AI31: =AF31*I31 -> 43062.5 | AJ31: =AH31+AI31 -> 66515 | AK31: 300 | AL31: 500 | AM31: =AK31+AL31 -> 800 | AN31: =AK31*H31 -> 9381 | AO31: =AL31*I31 -> 17225 | AP31: =AN31+AO31 -> 26606 | AQ31: =S31+Y31+AE31+AK31+M31 -> 2400 | AR31: =T31+Z31+AF31+AL31+N31 -> 3750 | AS31: =AQ31+AR31 -> 6150 | AT31: =V31+AB31+AH31+AN31+P31 -> 75048 | AU31: =W31+AC31+AI31+AO31+Q31 -> 129187.5 | AV31: =AT31+AU31 -> 204235.5 | AX31: =X31+AD31+AJ31+AP31+R31 -> 204235.5
A32: 23 | B32: CHIMALTENANGO | C32: ACATENANGO | D32: ACATENANGO | E32: FIJO | F32: 150 | G32: 200 | H32: 30.09 | I32: 33.15 | J32: CONTRATO ABIERTO | K32: REGION 5 | L32: BANQUETES DE GUATEMALA, S.A. | O32: =M32+N32 -> 0 | P32: =M32*H32 -> 0 | Q32: =N32*I32 -> 0 | R32: =P32+Q32 -> 0 | S32: 1350 | T32: 1800 | U32: =S32+T32 -> 3150 | V32: =S32*H32 -> 40621.5 | W32: =T32*I32 -> 59670 | X32: =V32+W32 -> 100291.5 | Y32: 450 | Z32: 600 | AA32: =Y32+Z32 -> 1050 | AB32: =Y32*H32 -> 13540.5 | AC32: =Z32*I32 -> 19890 | AD32: =AB32+AC32 -> 33430.5 | AE32: 750 | AF32: 1000 | AG32: =AE32+AF32 -> 1750 | AH32: =AE32*H32 -> 22567.5 | AI32: =AF32*I32 -> 33150 | AJ32: =AH32+AI32 -> 55717.5 | AK32: 450 | AL32: 600 | AM32: =AK32+AL32 -> 1050 | AN32: =AK32*H32 -> 13540.5 | AO32: =AL32*I32 -> 19890 | AP32: =AN32+AO32 -> 33430.5 | AQ32: =S32+Y32+AE32+AK32+M32 -> 3000 | AR32: =T32+Z32+AF32+AL32+N32 -> 4000 | AS32: =AQ32+AR32 -> 7000 | AT32: =V32+AB32+AH32+AN32+P32 -> 90270 | AU32: =W32+AC32+AI32+AO32+Q32 -> 132600 | AV32: =AT32+AU32 -> 222870 | AX32: =X32+AD32+AJ32+AP32+R32 -> 222870
A33: 24 | B33: CHIMALTENANGO | C33: EL TEJAR | D33: EL TEJAR | E33: FIJO | F33: 150 | G33: 200 | H33: 30.09 | I33: 33.15 | J33: CONTRATO ABIERTO | K33: REGION 5 | L33: BANQUETES DE GUATEMALA, S.A. | O33: =M33+N33 -> 0 | P33: =M33*H33 -> 0 | Q33: =N33*I33 -> 0 | R33: =P33+Q33 -> 0 | S33: 1350 | T33: 1795 | U33: =S33+T33 -> 3145 | V33: =S33*H33 -> 40621.5 | W33: =T33*I33 -> 59504.25 | X33: =V33+W33 -> 100125.75 | Y33: 450 | Z33: 600 | AA33: =Y33+Z33 -> 1050 | AB33: =Y33*H33 -> 13540.5 | AC33: =Z33*I33 -> 19890 | AD33: =AB33+AC33 -> 33430.5 | AE33: 750 | AF33: 1000 | AG33: =AE33+AF33 -> 1750 | AH33: =AE33*H33 -> 22567.5 | AI33: =AF33*I33 -> 33150 | AJ33: =AH33+AI33 -> 55717.5 | AK33: 450 | AL33: 600 | AM33: =AK33+AL33 -> 1050 | AN33: =AK33*H33 -> 13540.5 | AO33: =AL33*I33 -> 19890 | AP33: =AN33+AO33 -> 33430.5 | AQ33: =S33+Y33+AE33+AK33+M33 -> 3000 | AR33: =T33+Z33+AF33+AL33+N33 -> 3995 | AS33: =AQ33+AR33 -> 6995 | AT33: =V33+AB33+AH33+AN33+P33 -> 90270 | AU33: =W33+AC33+AI33+AO33+Q33 -> 132434.25 | AV33: =AT33+AU33 -> 222704.25 | AX33: =X33+AD33+AJ33+AP33+R33 -> 222704.25
A34: 25 | B34: CHIMALTENANGO | C34: PATZÚN | D34: PATZÚN | E34: FIJO | F34: 100 | G34: 175 | H34: 26 | I34: 27.5 | J34: LICITACION | K34: LOTE 16 | L34: TECNO SUMINISTROS, S.A. | O34: =M34+N34 -> 0 | P34: =M34*H34 -> 0 | Q34: =N34*I34 -> 0 | R34: =P34+Q34 -> 0 | S34: 900 | T34: 1575 | U34: =S34+T34 -> 2475 | V34: =S34*H34 -> 23400 | W34: =T34*I34 -> 43312.5 | X34: =V34+W34 -> 66712.5 | Y34: 300 | Z34: 525 | AA34: =Y34+Z34 -> 825 | AB34: =Y34*H34 -> 7800 | AC34: =Z34*I34 -> 14437.5 | AD34: =AB34+AC34 -> 22237.5 | AE34: 500 | AF34: 875 | AG34: =AE34+AF34 -> 1375 | AH34: =AE34*H34 -> 13000 | AI34: =AF34*I34 -> 24062.5 | AJ34: =AH34+AI34 -> 37062.5 | AK34: 300 | AL34: 525 | AM34: =AK34+AL34 -> 825 | AN34: =AK34*H34 -> 7800 | AO34: =AL34*I34 -> 14437.5 | AP34: =AN34+AO34 -> 22237.5 | AQ34: =S34+Y34+AE34+AK34+M34 -> 2000 | AR34: =T34+Z34+AF34+AL34+N34 -> 3500 | AS34: =AQ34+AR34 -> 5500 | AT34: =V34+AB34+AH34+AN34+P34 -> 52000 | AU34: =W34+AC34+AI34+AO34+Q34 -> 96250 | AV34: =AT34+AU34 -> 148250 | AX34: =X34+AD34+AJ34+AP34+R34 -> 148250
A35: 26 | B35: CHIMALTENANGO | C35: SAN MIGUEL POCHUTA | D35: SAN MIGUEL POCHUTA | E35: FIJO | F35: 100 | G35: 200 | H35: 26 | I35: 27.5 | J35: LICITACION | K35: LOTE 16 | L35: TECNO SUMINISTROS, S.A. | O35: =M35+N35 -> 0 | P35: =M35*H35 -> 0 | Q35: =N35*I35 -> 0 | R35: =P35+Q35 -> 0 | S35: 900 | T35: 1800 | U35: =S35+T35 -> 2700 | V35: =S35*H35 -> 23400 | W35: =T35*I35 -> 49500 | X35: =V35+W35 -> 72900 | Y35: 300 | Z35: 600 | AA35: =Y35+Z35 -> 900 | AB35: =Y35*H35 -> 7800 | AC35: =Z35*I35 -> 16500 | AD35: =AB35+AC35 -> 24300 | AE35: 500 | AF35: 1000 | AG35: =AE35+AF35 -> 1500 | AH35: =AE35*H35 -> 13000 | AI35: =AF35*I35 -> 27500 | AJ35: =AH35+AI35 -> 40500 | AK35: 0 | AL35: 0 | AM35: =AK35+AL35 -> 0 | AN35: =AK35*H35 -> 0 | AO35: =AL35*I35 -> 0 | AP35: =AN35+AO35 -> 0 | AQ35: =S35+Y35+AE35+AK35+M35 -> 1700 | AR35: =T35+Z35+AF35+AL35+N35 -> 3400 | AS35: =AQ35+AR35 -> 5100 | AT35: =V35+AB35+AH35+AN35+P35 -> 44200 | AU35: =W35+AC35+AI35+AO35+Q35 -> 93500 | AV35: =AT35+AU35 -> 137700 | AX35: =X35+AD35+AJ35+AP35+R35 -> 137700
A36: 27 | B36: CHIMALTENANGO | C36: SAN PEDRO YEPOCAPA | D36: SAN PEDRO YEPOCAPA | E36: MÓVIL | F36: 150 | G36: 200 | H36: 26 | I36: 27.5 | J36: LICITACION | K36: LOTE 16 | L36: TECNO SUMINISTROS, S.A. | O36: =M36+N36 -> 0 | P36: =M36*H36 -> 0 | Q36: =N36*I36 -> 0 | R36: =P36+Q36 -> 0 | S36: 1350 | T36: 1800 | U36: =S36+T36 -> 3150 | V36: =S36*H36 -> 35100 | W36: =T36*I36 -> 49500 | X36: =V36+W36 -> 84600 | Y36: 450 | Z36: 600 | AA36: =Y36+Z36 -> 1050 | AB36: =Y36*H36 -> 11700 | AC36: =Z36*I36 -> 16500 | AD36: =AB36+AC36 -> 28200 | AE36: 750 | AF36: 1000 | AG36: =AE36+AF36 -> 1750 | AH36: =AE36*H36 -> 19500 | AI36: =AF36*I36 -> 27500 | AJ36: =AH36+AI36 -> 47000 | AK36: 450 | AL36: 600 | AM36: =AK36+AL36 -> 1050 | AN36: =AK36*H36 -> 11700 | AO36: =AL36*I36 -> 16500 | AP36: =AN36+AO36 -> 28200 | AQ36: =S36+Y36+AE36+AK36+M36 -> 3000 | AR36: =T36+Z36+AF36+AL36+N36 -> 4000 | AS36: =AQ36+AR36 -> 7000 | AT36: =V36+AB36+AH36+AN36+P36 -> 78000 | AU36: =W36+AC36+AI36+AO36+Q36 -> 110000 | AV36: =AT36+AU36 -> 188000 | AX36: =X36+AD36+AJ36+AP36+R36 -> 188000
A37: 28 | B37: CHIQUIMULA | C37: CHIQUIMULA | D37: CHIQUIMULA | E37: MÓVIL TEMPORAL | F37: 150 | G37: 200 | H37: 31.27 | I37: 34.45 | J37: CONTRATO ABIERTO | K37: REGION 3 | L37: BANQUETES DE GUATEMALA, S.A. | O37: =M37+N37 -> 0 | P37: =M37*H37 -> 0 | Q37: =N37*I37 -> 0 | R37: =P37+Q37 -> 0 | S37: 900 | T37: 1000 | U37: =S37+T37 -> 1900 | V37: =S37*H37 -> 28143 | W37: =T37*I37 -> 34450 | X37: =V37+W37 -> 62593 | Y37: 450 | Z37: 400 | AA37: =Y37+Z37 -> 850 | AB37: =Y37*H37 -> 14071.5 | AC37: =Z37*I37 -> 13780 | AD37: =AB37+AC37 -> 27851.5 | AE37: 600 | AF37: 1000 | AG37: =AE37+AF37 -> 1600 | AH37: =AE37*H37 -> 18762 | AI37: =AF37*I37 -> 34450 | AJ37: =AH37+AI37 -> 53212 | AK37: 450 | AL37: 600 | AM37: =AK37+AL37 -> 1050 | AN37: =AK37*H37 -> 14071.5 | AO37: =AL37*I37 -> 20670 | AP37: =AN37+AO37 -> 34741.5 | AQ37: =S37+Y37+AE37+AK37+M37 -> 2400 | AR37: =T37+Z37+AF37+AL37+N37 -> 3000 | AS37: =AQ37+AR37 -> 5400 | AT37: =V37+AB37+AH37+AN37+P37 -> 75048 | AU37: =W37+AC37+AI37+AO37+Q37 -> 103350 | AV37: =AT37+AU37 -> 178398 | AX37: =X37+AD37+AJ37+AP37+R37 -> 178398
A38: 29 | B38: CHIQUIMULA | C38: CAMOTÁN | D38: CAMOTÁN | E38: FIJO | F38: 100 | G38: 150 | H38: 25 | I38: 28 | J38: LICITACION | K38: LOTE 17 | L38: PROVEEDORA DE ALIMENTOS EL ROSARIO | O38: =M38+N38 -> 0 | P38: =M38*H38 -> 0 | Q38: =N38*I38 -> 0 | R38: =P38+Q38 -> 0 | S38: 900 | T38: 1350 | U38: =S38+T38 -> 2250 | V38: =S38*H38 -> 22500 | W38: =T38*I38 -> 37800 | X38: =V38+W38 -> 60300 | Y38: 300 | Z38: 448 | AA38: =Y38+Z38 -> 748 | AB38: =Y38*H38 -> 7500 | AC38: =Z38*I38 -> 12544 | AD38: =AB38+AC38 -> 20044 | AE38: 500 | AF38: 750 | AG38: =AE38+AF38 -> 1250 | AH38: =AE38*H38 -> 12500 | AI38: =AF38*I38 -> 21000 | AJ38: =AH38+AI38 -> 33500 | AK38: 300 | AL38: 450 | AM38: =AK38+AL38 -> 750 | AN38: =AK38*H38 -> 7500 | AO38: =AL38*I38 -> 12600 | AP38: =AN38+AO38 -> 20100 | AQ38: =S38+Y38+AE38+AK38+M38 -> 2000 | AR38: =T38+Z38+AF38+AL38+N38 -> 2998 | AS38: =AQ38+AR38 -> 4998 | AT38: =V38+AB38+AH38+AN38+P38 -> 50000 | AU38: =W38+AC38+AI38+AO38+Q38 -> 83944 | AV38: =AT38+AU38 -> 133944 | AX38: =X38+AD38+AJ38+AP38+R38 -> 133944
A39: 30 | B39: CHIQUIMULA | C39: IPALA | D39: IPALA | E39: FIJO | F39: 100 | G39: 150 | H39: 31.27 | I39: 34.45 | J39: CONTRATO ABIERTO | K39: REGION 3 | L39: BANQUETES DE GUATEMALA, S.A. | O39: =M39+N39 -> 0 | P39: =M39*H39 -> 0 | Q39: =N39*I39 -> 0 | R39: =P39+Q39 -> 0 | S39: 900 | T39: 1342 | U39: =S39+T39 -> 2242 | V39: =S39*H39 -> 28143 | W39: =T39*I39 -> 46231.9 | X39: =V39+W39 -> 74374.9 | Y39: 300 | Z39: 450 | AA39: =Y39+Z39 -> 750 | AB39: =Y39*H39 -> 9381 | AC39: =Z39*I39 -> 15502.5 | AD39: =AB39+AC39 -> 24883.5 | AE39: 500 | AF39: 750 | AG39: =AE39+AF39 -> 1250 | AH39: =AE39*H39 -> 15635 | AI39: =AF39*I39 -> 25837.5 | AJ39: =AH39+AI39 -> 41472.5 | AK39: 300 | AL39: 450 | AM39: =AK39+AL39 -> 750 | AN39: =AK39*H39 -> 9381 | AO39: =AL39*I39 -> 15502.5 | AP39: =AN39+AO39 -> 24883.5 | AQ39: =S39+Y39+AE39+AK39+M39 -> 2000 | AR39: =T39+Z39+AF39+AL39+N39 -> 2992 | AS39: =AQ39+AR39 -> 4992 | AT39: =V39+AB39+AH39+AN39+P39 -> 62540 | AU39: =W39+AC39+AI39+AO39+Q39 -> 103074.4 | AV39: =AT39+AU39 -> 165614.4 | AX39: =X39+AD39+AJ39+AP39+R39 -> 165614.4
A40: 31 | B40: CHIQUIMULA | C40: JOCOTÁN | D40: JOCOTÁN | E40: FIJO | F40: 125 | G40: 200 | H40: 25 | I40: 28 | J40: LICITACION | K40: LOTE 17 | L40: PROVEEDORA DE ALIMENTOS EL ROSARIO | O40: =M40+N40 -> 0 | P40: =M40*H40 -> 0 | Q40: =N40*I40 -> 0 | R40: =P40+Q40 -> 0 | S40: 1125 | T40: 1790 | U40: =S40+T40 -> 2915 | V40: =S40*H40 -> 28125 | W40: =T40*I40 -> 50120 | X40: =V40+W40 -> 78245 | Y40: 375 | Z40: 600 | AA40: =Y40+Z40 -> 975 | AB40: =Y40*H40 -> 9375 | AC40: =Z40*I40 -> 16800 | AD40: =AB40+AC40 -> 26175 | AE40: 625 | AF40: 995 | AG40: =AE40+AF40 -> 1620 | AH40: =AE40*H40 -> 15625 | AI40: =AF40*I40 -> 27860 | AJ40: =AH40+AI40 -> 43485 | AK40: 375 | AL40: 596 | AM40: =AK40+AL40 -> 971 | AN40: =AK40*H40 -> 9375 | AO40: =AL40*I40 -> 16688 | AP40: =AN40+AO40 -> 26063 | AQ40: =S40+Y40+AE40+AK40+M40 -> 2500 | AR40: =T40+Z40+AF40+AL40+N40 -> 3981 | AS40: =AQ40+AR40 -> 6481 | AT40: =V40+AB40+AH40+AN40+P40 -> 62500 | AU40: =W40+AC40+AI40+AO40+Q40 -> 111468 | AV40: =AT40+AU40 -> 173968 | AX40: =X40+AD40+AJ40+AP40+R40 -> 173968
A41: 32 | B41: CHIQUIMULA | C41: OLOPA | D41: OLOPA | E41: FIJO | F41: 75 | G41: 125 | H41: 25 | I41: 28 | J41: LICITACION | K41: LOTE 17 | L41: PROVEEDORA DE ALIMENTOS EL ROSARIO | O41: =M41+N41 -> 0 | P41: =M41*H41 -> 0 | Q41: =N41*I41 -> 0 | R41: =P41+Q41 -> 0 | S41: 675 | T41: 1103 | U41: =S41+T41 -> 1778 | V41: =S41*H41 -> 16875 | W41: =T41*I41 -> 30884 | X41: =V41+W41 -> 47759 | Y41: 225 | Z41: 355 | AA41: =Y41+Z41 -> 580 | AB41: =Y41*H41 -> 5625 | AC41: =Z41*I41 -> 9940 | AD41: =AB41+AC41 -> 15565 | AE41: 375 | AF41: 584 | AG41: =AE41+AF41 -> 959 | AH41: =AE41*H41 -> 9375 | AI41: =AF41*I41 -> 16352 | AJ41: =AH41+AI41 -> 25727 | AK41: 225 | AL41: 343 | AM41: =AK41+AL41 -> 568 | AN41: =AK41*H41 -> 5625 | AO41: =AL41*I41 -> 9604 | AP41: =AN41+AO41 -> 15229 | AQ41: =S41+Y41+AE41+AK41+M41 -> 1500 | AR41: =T41+Z41+AF41+AL41+N41 -> 2385 | AS41: =AQ41+AR41 -> 3885 | AT41: =V41+AB41+AH41+AN41+P41 -> 37500 | AU41: =W41+AC41+AI41+AO41+Q41 -> 66780 | AV41: =AT41+AU41 -> 104280 | AX41: =X41+AD41+AJ41+AP41+R41 -> 104280
...
