Workbook

Sheet RESUMEN EJECUTIVO
A1: MINISTERIO DE DESARROLLO SOCIAL | DIRECCIÓN DE PREVENCIÓN SOCIAL
A2: RESUMEN EJECUTIVO DE EJECUCIÓN FÍSICA Y FINANCIERA — JULIO 2026
A4: Programa Social | B4: Presupuesto Vigente (Q) | C4: Ejecución Financiera (Q) | D4: % Ejec. Financiera | E4: Meta Física Vigente | F4: Ejecución Física | G4: % Ejec. Física | U4: Programa | V4: % Financiera | W4: % Física
A5: =INTEGRADO!D4 -> Comedor Social | B5: =INTEGRADO!N4 -> 284581992 | C5: =INTEGRADO!O4 -> 1.291613e+08 | D5: =INTEGRADO!O4/INTEGRADO!N4 -> 0.45386323 | E5: =INTEGRADO!K4 -> 9219150 | F5: =INTEGRADO!L4 -> 5289587 | G5: =INTEGRADO!L4/INTEGRADO!K4 -> 0.57376081 | U5: =A5 -> Comedor Social | V5: =D5 -> 0.45386323 | W5: =G5 -> 0.57376081
A6: =INTEGRADO!D5 -> Bolsa Social | B6: =INTEGRADO!N5 -> 214000000 | C6: =INTEGRADO!O5 -> 133794050 | D6: =INTEGRADO!O5/INTEGRADO!N5 -> 0.62520584 | E6: =INTEGRADO!K5 -> 658461 | F6: =INTEGRADO!L5 -> 411674 | G6: =INTEGRADO!L5/INTEGRADO!K5 -> 0.62520635 | U6: =A6 -> Bolsa Social | V6: =D6 -> 0.62520584 | W6: =G6 -> 0.62520635
A7: =INTEGRADO!D6 -> Jóvenes Protagonistas | B7: =INTEGRADO!N6 -> 64869524 | C7: =INTEGRADO!O6 -> 14430924 | D7: =INTEGRADO!O6/INTEGRADO!N6 -> 0.22246076 | E7: =INTEGRADO!K6 -> 77500 | F7: =INTEGRADO!L6 -> 33556 | G7: =INTEGRADO!L6/INTEGRADO!K6 -> 0.43298065 | U7: =A7 -> Jóvenes Protagonistas | V7: =D7 -> 0.22246076 | W7: =G7 -> 0.43298065
A8: =INTEGRADO!D7 -> Beca Media | B8: =INTEGRADO!N7 -> 14663654 | C8: =INTEGRADO!O7 -> 11730000 | D8: =INTEGRADO!O7/INTEGRADO!N7 -> 0.79993704 | E8: =INTEGRADO!K7 -> 5865 | F8: =INTEGRADO!L7 -> 4691.8 | G8: =INTEGRADO!L7/INTEGRADO!K7 -> 0.7999659 | U8: =A8 -> Beca Media | V8: =D8 -> 0.79993704 | W8: =G8 -> 0.7999659
A9: =INTEGRADO!D8 -> Beca Superior | B9: =INTEGRADO!N8 -> 3860500 | C9: =INTEGRADO!O8 -> 2779200 | D9: =INTEGRADO!O8/INTEGRADO!N8 -> 0.71990675 | E9: =INTEGRADO!K8 -> 1544 | F9: =INTEGRADO!L8 -> 1111.68 | G9: =INTEGRADO!L8/INTEGRADO!K8 -> 0.72 | U9: =A9 -> Beca Superior | V9: =D9 -> 0.71990675 | W9: =G9 -> 0.72
A10: TOTAL DPS | B10: =SUM(B5:B9) -> 581975670 | C10: =SUM(C5:C9) -> 2.9189548e+08 | D10: =C10/B10 -> 0.50155958 | E10: =SUM(E5:E9) -> 9962520 | F10: =SUM(F5:F9) -> 5740620.5 | G10: =F10/E10 -> 0.57622173
A11: TABLA DINÁMICA — EJECUCIÓN FÍSICA Y FINANCIERA POR PROGRAMA, DEPARTAMENTO Y MES
A12: Municipio | B12: (Varios elementos)
A13: Unidad de Medida | B13: (Varios elementos)
B15: Etiquetas de columna
B16: 01 Enero | D16: 02 Febrero | F16: 03 Marzo | H16: 04 Abril | J16: 05 Mayo | L16: 06 Junio | N16: 07 Julio | P16: Total Suma de Financiera | Q16: Total Suma de Física
A17: Etiquetas de fila | B17: Suma de Financiera | C17: Suma de Física | D17: Suma de Financiera | E17: Suma de Física | F17: Suma de Financiera | G17: Suma de Física | H17: Suma de Financiera | I17: Suma de Física | J17: Suma de Financiera | K17: Suma de Física | L17: Suma de Financiera | M17: Suma de Física | N17: Suma de Financiera | O17: Suma de Física
A18: Comedor Social | B18: 0 | C18: 4650 | D18: 0 | E18: 5000 | F18: 344536.5 | G18: 5500 | H18: 196251 | I18: 4750 | J18: 169489.5 | K18: 4989 | L18: 178040.07 | M18: 5000 | N18: 178410 | O18: 5175 | P18: 1066727.1 | Q18: 35064
A19: HUEHUETENANGO | B19: 0 | C19: 4650 | D19: 0 | E19: 5000 | F19: 344536.5 | G19: 5500 | H19: 196251 | I19: 4750 | J19: 169489.5 | K19: 4989 | L19: 178040.07 | M19: 5000 | N19: 178410 | O19: 5175 | P19: 1066727.1 | Q19: 35064
A20: Total general | B20: 0 | C20: 4650 | D20: 0 | E20: 5000 | F20: 344536.5 | G20: 5500 | H20: 196251 | I20: 4750 | J20: 169489.5 | K20: 4989 | L20: 178040.07 | M20: 5000 | N20: 178410 | O20: 5175 | P20: 1066727.1 | Q20: 35064

Sheet INTEGRADO
C2: DIRECCION DE PREVENSIÓN SOCIAL 2025 | E2: PRESUPESTO GENERAL | I2: ="EJECUCION DE JULIO GS 2026 DPS" -> EJECUCION DE JULIO GS 2026 DPS | K2: EJECUCION FISICA 2026 | N2: EJECUCIÓN FINANCIERA 2026
C3: SUBDIRECCIÓN | D3: PROGRAMA SOCIAL | E3: PRESUPUESTO FINANCIERO INICIAL | F3: PRESUPUETO FINANCIERO VIGENTE | G3: EJECUCIÓN FINANCIERA | H3: % Ejecucion General | I3: FÍSICA | J3: FINANCIERA | K3: META FISICA VIGENTE | L3: EJECUTADO | M3: % Ejecución | N3: EJECUCIÓN VIGENTE | O3: EJECUCIÓN EJECUTADO | P3: % EJECUCIÓN
A4: x | B4: 211 | C4: COMEDORES | D4: Comedor Social | E4: 179849180 | F4: 318833963 | G4: 1.4228679e+08 | H4: =G4/F4 -> 0.44627238 | I4: 1066904 | J4: 25682209 | K4: 9219150 | L4: 5289587 | M4: =L4/K4 -> 0.57376081 | N4: 284581992 | O4: 1.291613e+08 | P4: =O4/N4 -> 0.45386323
A5: x | B5: 419 | C5: BOLSA DE ALIMENTOS | D5: Bolsa Social | E5: 117541070 | F5: 238384670 | G5: 1.4371802e+08 | H5: =G5/F5 -> 0.60288282 | I5: 55000 | J5: 17875000 | K5: 658461 | L5: 411674 | M5: =L5/K5 -> 0.62520635 | N5: 214000000 | O5: 133794050 | P5: =O5/N5 -> 0.62520584
C6: FAMILIAS SEGURAS | D6: Jóvenes Protagonistas | E6: 23753024 | F6: 64869524 | G6: 14430924 | H6: =G6/F6 -> 0.22246076 | I6: 4779 | J6: 4236525.6 | K6: 77500 | L6: 33556 | M6: =L6/K6 -> 0.43298065 | N6: 64869524 | O6: 14430924 | P6: =O6/N6 -> 0.22246076
A7: x | B7: 416 | C7: BECA EDUCACIÓN MEDIA | D7: Beca Media | E7: 15013686 | F7: 15543440 | G7: 12077710 | H7: =G7/F7 -> 0.77702939 | I7: 0 | J7: 0 | K7: 5865 | L7: 4691.8 | M7: =L7/K7 -> 0.7999659 | N7: 14663654 | O7: 11730000 | P7: =O7/N7 -> 0.79993704
A8: x | B8: 416 | C8: BECA EDUCACIÓN SUPERIOR | D8: Beca Superior | E8: 4787338 | F8: 5309438 | G8: 3457197.3 | H8: =G8/F8 -> 0.65114185 | I8: 0 | J8: 0 | K8: 1544 | L8: 1111.68 | M8: =L8/K8 -> 0.72 | N8: 3860500 | O8: 2779200 | P8: =O8/N8 -> 0.71990675

Sheet BECA MEDIA
A1: PROGRAMA SOCIAL "BECA EDUCACIÓN MEDIA"
A2: NO. | B2: DEPARTAMENTO | C2: MUNICIPIO | D2: UNIDAD DE MEDIDA | E2: PLANIFICACIÓN | G2: EJECUCIÓN 30 ENERO | J2: EJECUCIÓN 28 FEBRERO | M2: EJECUCIÓN 31 MARZO | P2: EJECUCIÓN 30 ABRIL | S2: EJECUCIÓN 31 MAYO | V2: EJECUCIÓN 30 JUNIO | Y2: EJECUCIÓN 31 JULIO | AB2: EJECUCIÓN 31 AGOSTO | AE2: EJECUCIÓN 30 SEPTIEMBRE | AH2: EJECUCIÓN 31 OCTUBRE | AK2: EJECUCIÓN 30 NOVIEMBRE | AN2: EJECUCIÓN 31 DICIEMBRE | AQ2: EJECUCIÓN TOTAL 2026
E3: FÍSICA | F3: FINANCIERA | G3: FÍSICA | H3: FINANCIERA | I3: Beneficiarios | J3: FÍSICA | K3: FINANCIERA | L3: Beneficiarios | M3: FÍSICA | N3: FINANCIERA | O3: Beneficiarios | P3: FÍSICA | Q3: FINANCIERA | R3: Beneficiarios | S3: FÍSICA | T3: FINANCIERA | U3: Beneficiarios | V3: FÍSICA | W3: FINANCIERA | X3: Beneficiarios | Y3: FÍSICA | Z3: FINANCIERA | AA3: Beneficiarios | AB3: FÍSICA | AC3: FINANCIERA | AD3: Beneficiarios | AE3: FÍSICA | AF3: FINANCIERA | AG3: Beneficiarios | AH3: FÍSICA | AI3: FINANCIERA | AJ3: Beneficiarios | AK3: FÍSICA | AL3: FINANCIERA | AM3: Beneficiarios | AN3: FÍSICA | AO3: FINANCIERA | AP3: Beneficiarios | AQ3: FÍSICA | AR3: FINANCIERA | AS3: Beneficiarios
A4: 1 | B4: ALTA VERAPAZ | C4: CAHABÓN | D4: Beca | E4: 20.4 | F4: =E4*2500 -> 51000 | G4: 0 | H4: 0 | I4: 0 | J4: 0 | K4: 0 | L4: 0 | M4: 5.6 | N4: 14000 | O4: 14 | P4: =Q4/2500 -> 4.8 | Q4: =R4*1000 -> 12000 | R4: 12 | S4: 0 | T4: 0 | U4: 0 | V4: =W4/2500 -> 10.4 | W4: 26000 | X4: 26 | Y4: 0 | Z4: 0 | AA4: 0 | AB4: 0 | AC4: 0 | AD4: 0 | AE4: 0 | AF4: 0 | AG4: 0 | AH4: 0 | AI4: 0 | AJ4: 0 | AK4: 0 | AL4: 0 | AM4: 0 | AN4: 0 | AO4: 0 | AP4: 0 | AQ4: =G4+J4+M4+P4+S4+V4+Y4+AB4+AE4+AH4+AK4+AN4 -> 20.8 | AR4: =H4+K4+N4+Q4+T4+W4+Z4+AC4+AF4+AI4+AL4+AO4 -> 52000 | AS4: 27
A5: 2 | B5: ALTA VERAPAZ | C5: CHAHAL | E5: 37.6 | F5: =E5*2500 -> 94000 | G5: 0 | H5: 0 | I5: 0 | J5: 0 | K5: 0 | L5: 0 | M5: 6 | N5: 15000 | O5: 15 | P5: =Q5/2500 -> 6.8 | Q5: =R5*1000 -> 17000 | R5: 17 | S5: 0 | T5: 0 | U5: 0 | V5: =W5/2500 -> 12.8 | W5: 32000 | X5: 32 | Y5: 0 | Z5: 0 | AA5: 0 | AB5: 0 | AC5: 0 | AD5: 0 | AE5: 0 | AF5: 0 | AG5: 0 | AH5: 0 | AI5: 0 | AJ5: 0 | AK5: 0 | AL5: 0 | AM5: 0 | AN5: 0 | AO5: 0 | AP5: 0 | AQ5: =G5+J5+M5+P5+S5+V5+Y5+AB5+AE5+AH5+AK5+AN5 -> 25.6 | AR5: =H5+K5+N5+Q5+T5+W5+Z5+AC5+AF5+AI5+AL5+AO5 -> 64000 | AS5: 32
A6: 3 | B6: ALTA VERAPAZ | C6: CHISEC | E6: 29.4 | F6: =E6*2500 -> 73500 | G6: 0 | H6: 0 | I6: 0 | J6: 0 | K6: 0 | L6: 0 | M6: 6.8 | N6: 17000 | O6: 17 | P6: =Q6/2500 -> 2.8 | Q6: =R6*1000 -> 7000 | R6: 7 | S6: 0 | T6: 0 | U6: 0 | V6: =W6/2500 -> 9.2 | W6: 23000 | X6: 23 | Y6: 0 | Z6: 0 | AA6: 0 | AB6: 0 | AC6: 0 | AD6: 0 | AE6: 0 | AF6: 0 | AG6: 0 | AH6: 0 | AI6: 0 | AJ6: 0 | AK6: 0 | AL6: 0 | AM6: 0 | AN6: 0 | AO6: 0 | AP6: 0 | AQ6: =G6+J6+M6+P6+S6+V6+Y6+AB6+AE6+AH6+AK6+AN6 -> 18.8 | AR6: =H6+K6+N6+Q6+T6+W6+Z6+AC6+AF6+AI6+AL6+AO6 -> 47000 | AS6: 25
A7: 4 | B7: ALTA VERAPAZ | C7: COBÁN | E7: 24.8 | F7: =E7*2500 -> 62000 | G7: 0 | H7: 0 | I7: 0 | J7: 0 | K7: 0 | L7: 0 | M7: 6 | N7: 15000 | O7: 15 | P7: =Q7/2500 -> 3.2 | Q7: =R7*1000 -> 8000 | R7: 8 | S7: 0 | T7: 0 | U7: 0 | V7: =W7/2500 -> 8.8 | W7: 22000 | X7: 22 | Y7: 0 | Z7: 0 | AA7: 0 | AB7: 0 | AC7: 0 | AD7: 0 | AE7: 0 | AF7: 0 | AG7: 0 | AH7: 0 | AI7: 0 | AJ7: 0 | AK7: 0 | AL7: 0 | AM7: 0 | AN7: 0 | AO7: 0 | AP7: 0 | AQ7: =G7+J7+M7+P7+S7+V7+Y7+AB7+AE7+AH7+AK7+AN7 -> 18 | AR7: =H7+K7+N7+Q7+T7+W7+Z7+AC7+AF7+AI7+AL7+AO7 -> 45000 | AS7: 23
A8: 5 | B8: ALTA VERAPAZ | C8: FRAY BARTOLOMÉ DE LAS CASAS | E8: 11.8 | F8: =E8*2500 -> 29500 | G8: 0 | H8: 0 | I8: 0 | J8: 0 | K8: 0 | L8: 0 | M8: 1.6 | N8: 4000 | O8: 4 | P8: =Q8/2500 -> 2.4 | Q8: =R8*1000 -> 6000 | R8: 6 | S8: 0 | T8: 0 | U8: 0 | V8: =W8/2500 -> 4 | W8: 10000 | X8: 10 | Y8: 0 | Z8: 0 | AA8: 0 | AB8: 0 | AC8: 0 | AD8: 0 | AE8: 0 | AF8: 0 | AG8: 0 | AH8: 0 | AI8: 0 | AJ8: 0 | AK8: 0 | AL8: 0 | AM8: 0 | AN8: 0 | AO8: 0 | AP8: 0 | AQ8: =G8+J8+M8+P8+S8+V8+Y8+AB8+AE8+AH8+AK8+AN8 -> 8 | AR8: =H8+K8+N8+Q8+T8+W8+Z8+AC8+AF8+AI8+AL8+AO8 -> 20000 | AS8: 10
A9: 6 | B9: ALTA VERAPAZ | C9: LANQUÍN | E9: 18 | F9: =E9*2500 -> 45000 | G9: 0 | H9: 0 | I9: 0 | J9: 0 | K9: 0 | L9: 0 | M9: 2.4 | N9: 6000 | O9: 6 | P9: =Q9/2500 -> 7.6 | Q9: =R9*1000 -> 19000 | R9: 19 | S9: 0 | T9: 0 | U9: 0 | V9: =W9/2500 -> 9.6 | W9: 24000 | X9: 24 | Y9: 0 | Z9: 0 | AA9: 0 | AB9: 0 | AC9: 0 | AD9: 0 | AE9: 0 | AF9: 0 | AG9: 0 | AH9: 0 | AI9: 0 | AJ9: 0 | AK9: 0 | AL9: 0 | AM9: 0 | AN9: 0 | AO9: 0 | AP9: 0 | AQ9: =G9+J9+M9+P9+S9+V9+Y9+AB9+AE9+AH9+AK9+AN9 -> 19.6 | AR9: =H9+K9+N9+Q9+T9+W9+Z9+AC9+AF9+AI9+AL9+AO9 -> 49000 | AS9: 25
A10: 7 | B10: ALTA VERAPAZ | C10: PANZÓS | E10: 27 | F10: =E10*2500 -> 67500 | G10: 0 | H10: 0 | I10: 0 | J10: 0 | K10: 0 | L10: 0 | M10: 6 | N10: 15000 | O10: 15 | P10: =Q10/2500 -> 4.8 | Q10: =R10*1000 -> 12000 | R10: 12 | S10: 0 | T10: 0 | U10: 0 | V10: =W10/2500 -> 10.4 | W10: 26000 | X10: 26 | Y10: 0 | Z10: 0 | AA10: 0 | AB10: 0 | AC10: 0 | AD10: 0 | AE10: 0 | AF10: 0 | AG10: 0 | AH10: 0 | AI10: 0 | AJ10: 0 | AK10: 0 | AL10: 0 | AM10: 0 | AN10: 0 | AO10: 0 | AP10: 0 | AQ10: =G10+J10+M10+P10+S10+V10+Y10+AB10+AE10+AH10+AK10+AN10 -> 21.2 | AR10: =H10+K10+N10+Q10+T10+W10+Z10+AC10+AF10+AI10+AL10+AO10 -> 53000 | AS10: 27
A11: 8 | B11: ALTA VERAPAZ | C11: RAXRUHÁ | E11: 16.4 | F11: =E11*2500 -> 41000 | G11: 0 | H11: 0 | I11: 0 | J11: 0 | K11: 0 | L11: 0 | M11: 4.4 | N11: 11000 | O11: 11 | P11: =Q11/2500 -> 0 | Q11: =R11*1000 -> 0 | R11: 0 | S11: 0 | T11: 0 | U11: 0 | V11: =W11/2500 -> 3.6 | W11: 9000 | X11: 9 | Y11: 0 | Z11: 0 | AA11: 0 | AB11: 0 | AC11: 0 | AD11: 0 | AE11: 0 | AF11: 0 | AG11: 0 | AH11: 0 | AI11: 0 | AJ11: 0 | AK11: 0 | AL11: 0 | AM11: 0 | AN11: 0 | AO11: 0 | AP11: 0 | AQ11: =G11+J11+M11+P11+S11+V11+Y11+AB11+AE11+AH11+AK11+AN11 -> 8 | AR11: =H11+K11+N11+Q11+T11+W11+Z11+AC11+AF11+AI11+AL11+AO11 -> 20000 | AS11: 11
A12: 9 | B12: ALTA VERAPAZ | C12: SAN CRISTÓBAL VERAPAZ | E12: 27.8 | F12: =E12*2500 -> 69500 | G12: 0 | H12: 0 | I12: 0 | J12: 0 | K12: 0 | L12: 0 | M12: 8.8 | N12: 22000 | O12: 22 | P12: =Q12/2500 -> 2.8 | Q12: =R12*1000 -> 7000 | R12: 7 | S12: 0 | T12: 0 | U12: 0 | V12: =W12/2500 -> 11.2 | W12: 28000 | X12: 28 | Y12: 0 | Z12: 0 | AA12: 0 | AB12: 0 | AC12: 0 | AD12: 0 | AE12: 0 | AF12: 0 | AG12: 0 | AH12: 0 | AI12: 0 | AJ12: 0 | AK12: 0 | AL12: 0 | AM12: 0 | AN12: 0 | AO12: 0 | AP12: 0 | AQ12: =G12+J12+M12+P12+S12+V12+Y12+AB12+AE12+AH12+AK12+AN12 -> 22.8 | AR12: =H12+K12+N12+Q12+T12+W12+Z12+AC12+AF12+AI12+AL12+AO12 -> 57000 | AS12: 30
A13: 10 | B13: ALTA VERAPAZ | C13: SAN JUAN CHAMELCO | E13: 7 | F13: =E13*2500 -> 17500 | G13: 0 | H13: 0 | I13: 0 | J13: 0 | K13: 0 | L13: 0 | M13: 1.6 | N13: 4000 | O13: 4 | P13: =Q13/2500 -> 1.2 | Q13: =R13*1000 -> 3000 | R13: 3 | S13: 0 | T13: 0 | U13: 0 | V13: =W13/2500 -> 2.4 | W13: 6000 | X13: 6 | Y13: 0 | Z13: 0 | AA13: 0 | AB13: 0 | AC13: 0 | AD13: 0 | AE13: 0 | AF13: 0 | AG13: 0 | AH13: 0 | AI13: 0 | AJ13: 0 | AK13: 0 | AL13: 0 | AM13: 0 | AN13: 0 | AO13: 0 | AP13: 0 | AQ13: =G13+J13+M13+P13+S13+V13+Y13+AB13+AE13+AH13+AK13+AN13 -> 5.2 | AR13: =H13+K13+N13+Q13+T13+W13+Z13+AC13+AF13+AI13+AL13+AO13 -> 13000 | AS13: 7
A14: 11 | B14: ALTA VERAPAZ | C14: SAN PEDRO CARCHÁ | E14: 6.2 | F14: =E14*2500 -> 15500 | G14: 0 | H14: 0 | I14: 0 | J14: 0 | K14: 0 | L14: 0 | M14: 1.6 | N14: 4000 | O14: 4 | P14: =Q14/2500 -> 4 | Q14: =R14*1000 -> 10000 | R14: 10 | S14: 0 | T14: 0 | U14: 0 | V14: =W14/2500 -> 5.6 | W14: 14000 | X14: 14 | Y14: 0 | Z14: 0 | AA14: 0 | AB14: 0 | AC14: 0 | AD14: 0 | AE14: 0 | AF14: 0 | AG14: 0 | AH14: 0 | AI14: 0 | AJ14: 0 | AK14: 0 | AL14: 0 | AM14: 0 | AN14: 0 | AO14: 0 | AP14: 0 | AQ14: =G14+J14+M14+P14+S14+V14+Y14+AB14+AE14+AH14+AK14+AN14 -> 11.2 | AR14: =H14+K14+N14+Q14+T14+W14+Z14+AC14+AF14+AI14+AL14+AO14 -> 28000 | AS14: 15
A15: 12 | B15: ALTA VERAPAZ | C15: SANTA CATALINA LA TINTA | E15: 12.6 | F15: =E15*2500 -> 31500 | G15: 0 | H15: 0 | I15: 0 | J15: 0 | K15: 0 | L15: 0 | M15: 2 | N15: 5000 | O15: 5 | P15: =Q15/2500 -> 1.2 | Q15: =R15*1000 -> 3000 | R15: 3 | S15: 0 | T15: 0 | U15: 0 | V15: =W15/2500 -> 2.8 | W15: 7000 | X15: 7 | Y15: 0 | Z15: 0 | AA15: 0 | AB15: 0 | AC15: 0 | AD15: 0 | AE15: 0 | AF15: 0 | AG15: 0 | AH15: 0 | AI15: 0 | AJ15: 0 | AK15: 0 | AL15: 0 | AM15: 0 | AN15: 0 | AO15: 0 | AP15: 0 | AQ15: =G15+J15+M15+P15+S15+V15+Y15+AB15+AE15+AH15+AK15+AN15 -> 6 | AR15: =H15+K15+N15+Q15+T15+W15+Z15+AC15+AF15+AI15+AL15+AO15 -> 15000 | AS15: 8
A16: 13 | B16: ALTA VERAPAZ | C16: SANTA CRUZ VERAPAZ | E16: 27.8 | F16: =E16*2500 -> 69500 | G16: 0 | H16: 0 | I16: 0 | J16: 0 | K16: 0 | L16: 0 | M16: 8 | N16: 20000 | O16: 20 | P16: =Q16/2500 -> 6 | Q16: =R16*1000 -> 15000 | R16: 15 | S16: 0 | T16: 0 | U16: 0 | V16: =W16/2500 -> 14 | W16: 35000 | X16: 35 | Y16: 0 | Z16: 0 | AA16: 0 | AB16: 0 | AC16: 0 | AD16: 0 | AE16: 0 | AF16: 0 | AG16: 0 | AH16: 0 | AI16: 0 | AJ16: 0 | AK16: 0 | AL16: 0 | AM16: 0 | AN16: 0 | AO16: 0 | AP16: 0 | AQ16: =G16+J16+M16+P16+S16+V16+Y16+AB16+AE16+AH16+AK16+AN16 -> 28 | AR16: =H16+K16+N16+Q16+T16+W16+Z16+AC16+AF16+AI16+AL16+AO16 -> 70000 | AS16: 36
... A20: 17 | B20: ALTA VERAPAZ | C20: TUCURÚ | E20: 12.8 | F20: =E20*2500 -> 32000 | G20: 0 | H20: 0 | I20: 0 | J20: 0 | K20: 0 | L20: 0 | M20: 3.6 | N20: 9000 | O20: 9 | P20: =Q20/2500 -> 2 | Q20: =R20*1000 -> 5000 | R20: 5 | S20: 0 | T20: 0 | U20: 0 | V20: =W20/2500 -> 5.6 | W20: 14000 | X20: 14 | Y20: 0 | Z20: 0 | AA20: 0 | AB20: 0 | AC20: 0 | AD20: 0 | AE20: 0 | AF20: 0 | AG20: 0 | AH20: 0 | AI20: 0 | AJ20: 0 | AK20: 0 | AL20: 0 | AM20: 0 | AN20: 0 | AO20: 0 | AP20: 0 | AQ20: =G20+J20+M20+P20+S20+V20+Y20+AB20+AE20+AH20+AK20+AN20 -> 11.2 | AR20: =H20+K20+N20+Q20+T20+W20+Z20+AC20+AF20+AI20+AL20+AO20 -> 28000 | AS20: 14
A21: 18 | B21: BAJA VERAPAZ | C21: CUBULCO | D21: Beca | E21: 12.4 | F21: =E21*2500 -> 31000 | G21: 0 | H21: 0 | I21: 0 | J21: 0 | K21: 0 | L21: 0 | M21: 4.8 | N21: 12000 | O21: 12 | P21: =Q21/2500 -> 1.2 | Q21: =R21*1000 -> 3000 | R21: 3 | S21: 0 | T21: 0 | U21: 0 | V21: =W21/2500 -> 6 | W21: 15000 | X21: 15 | Y21: 0 | Z21: 0 | AA21: 0 | AB21: 0 | AC21: 0 | AD21: 0 | AE21: 0 | AF21: 0 | AG21: 0 | AH21: 0 | AI21: 0 | AJ21: 0 | AK21: 0 | AL21: 0 | AM21: 0 | AN21: 0 | AO21: 0 | AP21: 0 | AQ21: =G21+J21+M21+P21+S21+V21+Y21+AB21+AE21+AH21+AK21+AN21 -> 12 | AR21: =H21+K21+N21+Q21+T21+W21+Z21+AC21+AF21+AI21+AL21+AO21 -> 30000 | AS21: 15
A22: 19 | B22: BAJA VERAPAZ | C22: EL CHOL | E22: 23.8 | F22: =E22*2500 -> 59500 | G22: 0 | H22: 0 | I22: 0 | J22: 0 | K22: 0 | L22: 0 | M22: 8.4 | N22: 21000 | O22: 21 | P22: =Q22/2500 -> 3.6 | Q22: =R22*1000 -> 9000 | R22: 9 | S22: 0 | T22: 0 | U22: 0 | V22: =W22/2500 -> 11.6 | W22: 29000 | X22: 29 | Y22: 0 | Z22: 0 | AA22: 0 | AB22: 0 | AC22: 0 | AD22: 0 | AE22: 0 | AF22: 0 | AG22: 0 | AH22: 0 | AI22: 0 | AJ22: 0 | AK22: 0 | AL22: 0 | AM22: 0 | AN22: 0 | AO22: 0 | AP22: 0 | AQ22: =G22+J22+M22+P22+S22+V22+Y22+AB22+AE22+AH22+AK22+AN22 -> 23.6 | AR22: =H22+K22+N22+Q22+T22+W22+Z22+AC22+AF22+AI22+AL22+AO22 -> 59000 | AS22: 30
A23: 20 | B23: BAJA VERAPAZ | C23: GRANADOS | E23: 10 | F23: =E23*2500 -> 25000 | G23: 0 | H23: 0 | I23: 0 | J23: 0 | K23: 0 | L23: 0 | M23: 3.2 | N23: 8000 | O23: 8 | P23: =Q23/2500 -> 2 | Q23: =R23*1000 -> 5000 | R23: 5 | S23: 0 | T23: 0 | U23: 0 | V23: =W23/2500 -> 5.2 | W23: 13000 | X23: 13 | Y23: 0 | Z23: 0 | AA23: 0 | AB23: 0 | AC23: 0 | AD23: 0 | AE23: 0 | AF23: 0 | AG23: 0 | AH23: 0 | AI23: 0 | AJ23: 0 | AK23: 0 | AL23: 0 | AM23: 0 | AN23: 0 | AO23: 0 | AP23: 0 | AQ23: =G23+J23+M23+P23+S23+V23+Y23+AB23+AE23+AH23+AK23+AN23 -> 10.4 | AR23: =H23+K23+N23+Q23+T23+W23+Z23+AC23+AF23+AI23+AL23+AO23 -> 26000 | AS23: 13
A24: 21 | B24: BAJA VERAPAZ | C24: PURULHÁ | E24: 25.8 | F24: =E24*2500 -> 64500 | G24: 0 | H24: 0 | I24: 0 | J24: 0 | K24: 0 | L24: 0 | M24: 8 | N24: 20000 | O24: 20 | P24: =Q24/2500 -> 2.8 | Q24: =R24*1000 -> 7000 | R24: 7 | S24: 0 | T24: 0 | U24: 0 | V24: =W24/2500 -> 10.4 | W24: 26000 | X24: 26 | Y24: 0 | Z24: 0 | AA24: 0 | AB24: 0 | AC24: 0 | AD24: 0 | AE24: 0 | AF24: 0 | AG24: 0 | AH24: 0 | AI24: 0 | AJ24: 0 | AK24: 0 | AL24: 0 | AM24: 0 | AN24: 0 | AO24: 0 | AP24: 0 | AQ24: =G24+J24+M24+P24+S24+V24+Y24+AB24+AE24+AH24+AK24+AN24 -> 21.2 | AR24: =H24+K24+N24+Q24+T24+W24+Z24+AC24+AF24+AI24+AL24+AO24 -> 53000 | AS24: 27
A25: 22 | B25: BAJA VERAPAZ | C25: RABINAL | E25: 8 | F25: =E25*2500 -> 20000 | G25: 0 | H25: 0 | I25: 0 | J25: 0 | K25: 0 | L25: 0 | M25: 1.6 | N25: 4000 | O25: 4 | P25: =Q25/2500 -> 1.2 | Q25: =R25*1000 -> 3000 | R25: 3 | S25: 0 | T25: 0 | U25: 0 | V25: =W25/2500 -> 2.8 | W25: 7000 | X25: 7 | Y25: 0 | Z25: 0 | AA25: 0 | AB25: 0 | AC25: 0 | AD25: 0 | AE25: 0 | AF25: 0 | AG25: 0 | AH25: 0 | AI25: 0 | AJ25: 0 | AK25: 0 | AL25: 0 | AM25: 0 | AN25: 0 | AO25: 0 | AP25: 0 | AQ25: =G25+J25+M25+P25+S25+V25+Y25+AB25+AE25+AH25+AK25+AN25 -> 5.6 | AR25: =H25+K25+N25+Q25+T25+W25+Z25+AC25+AF25+AI25+AL25+AO25 -> 14000 | AS25: 7
A26: 23 | B26: BAJA VERAPAZ | C26: SALAMÁ | E26: 14.4 | F26: =E26*2500 -> 36000 | G26: 0 | H26: 0 | I26: 0 | J26: 0 | K26: 0 | L26: 0 | M26: 3.6 | N26: 9000 | O26: 9 | P26: =Q26/2500 -> 0.8 | Q26: =R26*1000 -> 2000 | R26: 2 | S26: 0 | T26: 0 | U26: 0 | V26: =W26/2500 -> 4.4 | W26: 11000 | X26: 11 | Y26: 0 | Z26: 0 | AA26: 0 | AB26: 0 | AC26: 0 | AD26: 0 | AE26: 0 | AF26: 0 | AG26: 0 | AH26: 0 | AI26: 0 | AJ26: 0 | AK26: 0 | AL26: 0 | AM26: 0 | AN26: 0 | AO26: 0 | AP26: 0 | AQ26: =G26+J26+M26+P26+S26+V26+Y26+AB26+AE26+AH26+AK26+AN26 -> 8.8 | AR26: =H26+K26+N26+Q26+T26+W26+Z26+AC26+AF26+AI26+AL26+AO26 -> 22000 | AS26: 11
A27: 24 | B27: BAJA VERAPAZ | C27: SAN JERÓNIMO | E27: 22.8 | F27: =E27*2500 -> 57000 | G27: 0 | H27: 0 | I27: 0 | J27: 0 | K27: 0 | L27: 0 | M27: 6.8 | N27: 17000 | O27: 17 | P27: =Q27/2500 -> 1.6 | Q27: =R27*1000 -> 4000 | R27: 4 | S27: 0 | T27: 0 | U27: 0 | V27: =W27/2500 -> 8.4 | W27: 21000 | X27: 21 | Y27: 0 | Z27: 0 | AA27: 0 | AB27: 0 | AC27: 0 | AD27: 0 | AE27: 0 | AF27: 0 | AG27: 0 | AH27: 0 | AI27: 0 | AJ27: 0 | AK27: 0 | AL27: 0 | AM27: 0 | AN27: 0 | AO27: 0 | AP27: 0 | AQ27: =G27+J27+M27+P27+S27+V27+Y27+AB27+AE27+AH27+AK27+AN27 -> 16.8 | AR27: =H27+K27+N27+Q27+T27+W27+Z27+AC27+AF27+AI27+AL27+AO27 -> 42000 | AS27: 21
A28: 25 | B28: BAJA VERAPAZ | C28: SAN MIGUEL CHICAJ | E28: 16.4 | F28: =E28*2500 -> 41000 | G28: 0 | H28: 0 | I28: 0 | J28: 0 | K28: 0 | L28: 0 | M28: 6 | N28: 15000 | O28: 15 | P28: =Q28/2500 -> 2.4 | Q28: =R28*1000 -> 6000 | R28: 6 | S28: 0 | T28: 0 | U28: 0 | V28: =W28/2500 -> 8.4 | W28: 21000 | X28: 21 | Y28: 0 | Z28: 0 | AA28: 0 | AB28: 0 | AC28: 0 | AD28: 0 | AE28: 0 | AF28: 0 | AG28: 0 | AH28: 0 | AI28: 0 | AJ28: 0 | AK28: 0 | AL28: 0 | AM28: 0 | AN28: 0 | AO28: 0 | AP28: 0 | AQ28: =G28+J28+M28+P28+S28+V28+Y28+AB28+AE28+AH28+AK28+AN28 -> 16.8 | AR28: =H28+K28+N28+Q28+T28+W28+Z28+AC28+AF28+AI28+AL28+AO28 -> 42000 | AS28: 21
A29: 26 | B29: CHIMALTENANGO | C29: ACATENANGO | E29: 11.4 | F29: =E29*2500 -> 28500 | G29: 0 | H29: 0 | I29: 0 | J29: 0 | K29: 0 | L29: 0 | M29: 2.4 | N29: 6000 | O29: 6 | P29: =Q29/2500 -> 0.8 | Q29: =R29*1000 -> 2000 | R29: 2 | S29: 0 | T29: 0 | U29: 0 | V29: =W29/2500 -> 3.2 | W29: 8000 | X29: 8 | Y29: 0 | Z29: 0 | AA29: 0 | AB29: 0 | AC29: 0 | AD29: 0 | AE29: 0 | AF29: 0 | AG29: 0 | AH29: 0 | AI29: 0 | AJ29: 0 | AK29: 0 | AL29: 0 | AM29: 0 | AN29: 0 | AO29: 0 | AP29: 0 | AQ29: =G29+J29+M29+P29+S29+V29+Y29+AB29+AE29+AH29+AK29+AN29 -> 6.4 | AR29: =H29+K29+N29+Q29+T29+W29+Z29+AC29+AF29+AI29+AL29+AO29 -> 16000 | AS29: 8
A30: 27 | B30: CHIMALTENANGO | C30: CHIMALTENANGO | E30: 23.6 | F30: =E30*2500 -> 59000 | G30: 0 | H30: 0 | I30: 0 | J30: 0 | K30: 0 | L30: 0 | M30: 5.6 | N30: 14000 | O30: 14 | P30: =Q30/2500 -> 3.2 | Q30: =R30*1000 -> 8000 | R30: 8 | S30: 0 | T30: 0 | U30: 0 | V30: =W30/2500 -> 8.8 | W30: 22000 | X30: 22 | Y30: 0 | Z30: 0 | AA30: 0 | AB30: 0 | AC30: 0 | AD30: 0 | AE30: 0 | AF30: 0 | AG30: 0 | AH30: 0 | AI30: 0 | AJ30: 0 | AK30: 0 | AL30: 0 | AM30: 0 | AN30: 0 | AO30: 0 | AP30: 0 | AQ30: =G30+J30+M30+P30+S30+V30+Y30+AB30+AE30+AH30+AK30+AN30 -> 17.6 | AR30: =H30+K30+N30+Q30+T30+W30+Z30+AC30+AF30+AI30+AL30+AO30 -> 44000 | AS30: 22
A31: 28 | B31: CHIMALTENANGO | C31: COMALAPA | E31: 18 | F31: =E31*2500 -> 45000 | G31: 0 | H31: 0 | I31: 0 | J31: 0 | K31: 0 | L31: 0 | M31: 3.2 | N31: 8000 | O31: 8 | P31: =Q31/2500 -> 3.2 | Q31: =R31*1000 -> 8000 | R31: 8 | S31: 0 | T31: 0 | U31: 0 | V31: =W31/2500 -> 6.4 | W31: 16000 | X31: 16 | Y31: 0 | Z31: 0 | AA31: 0 | AB31: 0 | AC31: 0 | AD31: 0 | AE31: 0 | AF31: 0 | AG31: 0 | AH31: 0 | AI31: 0 | AJ31: 0 | AK31: 0 | AL31: 0 | AM31: 0 | AN31: 0 | AO31: 0 | AP31: 0 | AQ31: =G31+J31+M31+P31+S31+V31+Y31+AB31+AE31+AH31+AK31+AN31 -> 12.8 | AR31: =H31+K31+N31+Q31+T31+W31+Z31+AC31+AF31+AI31+AL31+AO31 -> 32000 | AS31: 16
A32: 29 | B32: CHIMALTENANGO | C32: EL TEJAR | E32: 16.4 | F32: =E32*2500 -> 41000 | G32: 0 | H32: 0 | I32: 0 | J32: 0 | K32: 0 | L32: 0 | M32: 5.2 | N32: 13000 | O32: 13 | P32: =Q32/2500 -> 1.2 | Q32: =R32*1000 -> 3000 | R32: 3 | S32: 0 | T32: 0 | U32: 0 | V32: =W32/2500 -> 5.6 | W32: 14000 | X32: 14 | Y32: 0 | Z32: 0 | AA32: 0 | AB32: 0 | AC32: 0 | AD32: 0 | AE32: 0 | AF32: 0 | AG32: 0 | AH32: 0 | AI32: 0 | AJ32: 0 | AK32: 0 | AL32: 0 | AM32: 0 | AN32: 0 | AO32: 0 | AP32: 0 | AQ32: =G32+J32+M32+P32+S32+V32+Y32+AB32+AE32+AH32+AK32+AN32 -> 12 | AR32: =H32+K32+N32+Q32+T32+W32+Z32+AC32+AF32+AI32+AL32+AO32 -> 30000 | AS32: 16
A33: 30 | B33: CHIMALTENANGO | C33: PARRAMOS | E33: 19.6 | F33: =E33*2500 -> 49000 | G33: 0 | H33: 0 | I33: 0 | J33: 0 | K33: 0 | L33: 0 | M33: 4 | N33: 10000 | O33: 10 | P33: =Q33/2500 -> 4 | Q33: =R33*1000 -> 10000 | R33: 10 | S33: 0 | T33: 0 | U33: 0 | V33: =W33/2500 -> 8 | W33: 20000 | X33: 20 | Y33: 0 | Z33: 0 | AA33: 0 | AB33: 0 | AC33: 0 | AD33: 0 | AE33: 0 | AF33: 0 | AG33: 0 | AH33: 0 | AI33: 0 | AJ33: 0 | AK33: 0 | AL33: 0 | AM33: 0 | AN33: 0 | AO33: 0 | AP33: 0 | AQ33: =G33+J33+M33+P33+S33+V33+Y33+AB33+AE33+AH33+AK33+AN33 -> 16 | AR33: =H33+K33+N33+Q33+T33+W33+Z33+AC33+AF33+AI33+AL33+AO33 -> 40000 | AS33: 22
... A37: 34 | B37: CHIMALTENANGO | C37: SAN ANDRÉS ITZAPA | E37: 20 | F37: =E37*2500 -> 50000 | G37: 0 | H37: 0 | I37: 0 | J37: 0 | K37: 0 | L37: 0 | M37: 3.6 | N37: 9000 | O37: 9 | P37: =Q37/2500 -> 4.4 | Q37: =R37*1000 -> 11000 | R37: 11 | S37: 0 | T37: 0 | U37: 0 | V37: =W37/2500 -> 7.6 | W37: 19000 | X37: 19 | Y37: 0 | Z37: 0 | AA37: 0 | AB37: 0 | AC37: 0 | AD37: 0 | AE37: 0 | AF37: 0 | AG37: 0 | AH37: 0 | AI37: 0 | AJ37: 0 | AK37: 0 | AL37: 0 | AM37: 0 | AN37: 0 | AO37: 0 | AP37: 0 | AQ37: =G37+J37+M37+P37+S37+V37+Y37+AB37+AE37+AH37+AK37+AN37 -> 15.6 | AR37: =H37+K37+N37+Q37+T37+W37+Z37+AC37+AF37+AI37+AL37+AO37 -> 39000 | AS37: 20
A38: 35 | B38: CHIMALTENANGO | C38: SAN JOSÉ POAQUIL | D38: Beca | E38: 14 | F38: =E38*2500 -> 35000 | G38: 0 | H38: 0 | I38: 0 | J38: 0 | K38: 0 | L38: 0 | M38: 2.8 | N38: 7000 | O38: 7 | P38: =Q38/2500 -> 4.8 | Q38: =R38*1000 -> 12000 | R38: 12 | S38: 0 | T38: 0 | U38: 0 | V38: =W38/2500 -> 7.6 | W38: 19000 | X38: 19 | Y38: 0 | Z38: 0 | AA38: 0 | AB38: 0 | AC38: 0 | AD38: 0 | AE38: 0 | AF38: 0 | AG38: 0 | AH38: 0 | AI38: 0 | AJ38: 0 | AK38: 0 | AL38: 0 | AM38: 0 | AN38: 0 | AO38: 0 | AP38: 0 | AQ38: =G38+J38+M38+P38+S38+V38+Y38+AB38+AE38+AH38+AK38+AN38 -> 15.2 | AR38: =H38+K38+N38+Q38+T38+W38+Z38+AC38+AF38+AI38+AL38+AO38 -> 38000 | AS38: 19
A39: 36 | B39: CHIMALTENANGO | C39: SAN MARTÍN JILOTEPEQUE | E39: 8.4 | F39: =E39*2500 -> 21000 | G39: 0 | H39: 0 | I39: 0 | J39: 0 | K39: 0 | L39: 0 | M39: 2.4 | N39: 6000 | O39: 6 | P39: =Q39/2500 -> 0 | Q39: =R39*1000 -> 0 | R39: 0 | S39: 0 | T39: 0 | U39: 0 | V39: =W39/2500 -> 2.4 | W39: 6000 | X39: 6 | Y39: 0 | Z39: 0 | AA39: 0 | AB39: 0 | AC39: 0 | AD39: 0 | AE39: 0 | AF39: 0 | AG39: 0 | AH39: 0 | AI39: 0 | AJ39: 0 | AK39: 0 | AL39: 0 | AM39: 0 | AN39: 0 | AO39: 0 | AP39: 0 | AQ39: =G39+J39+M39+P39+S39+V39+Y39+AB39+AE39+AH39+AK39+AN39 -> 4.8 | AR39: =H39+K39+N39+Q39+T39+W39+Z39+AC39+AF39+AI39+AL39+AO39 -> 12000 | AS39: 6
A40: 37 | B40: CHIMALTENANGO | C40: SANTA APOLONIA | E40: 17.2 | F40: =E40*2500 -> 43000 | G40: 0 | H40: 0 | I40: 0 | J40: 0 | K40: 0 | L40: 0 | M40: 5.2 | N40: 13000 | O40: 13 | P40: =Q40/2500 -> 0 | Q40: =R40*1000 -> 0 | R40: 0 | S40: 0 | T40: 0 | U40: 0 | V40: =W40/2500 -> 5.2 | W40: 13000 | X40: 13 | Y40: 0 | Z40: 0 | AA40: 0 | AB40: 0 | AC40: 0 | AD40: 0 | AE40: 0 | AF40: 0 | AG40: 0 | AH40: 0 | AI40: 0 | AJ40: 0 | AK40: 0 | AL40: 0 | AM40: 0 | AN40: 0 | AO40: 0 | AP40: 0 | AQ40: =G40+J40+M40+P40+S40+V40+Y40+AB40+AE40+AH40+AK40+AN40 -> 10.4 | AR40: =H40+K40+N40+Q40+T40+W40+Z40+AC40+AF40+AI40+AL40+AO40 -> 26000 | AS40: 13
A41: 38 | B41: CHIMALTENANGO | C41: SANTA CRUZ BALANYÁ | E41: 14.8 | F41: =E41*2500 -> 37000 | G41: 0 | H41: 0 | I41: 0 | J41: 0 | K41: 0 | L41: 0 | M41: 4.4 | N41: 11000 | O41: 11 | P41: =Q41/2500 -> 1.6 | Q41: =R41*1000 -> 4000 | R41: 4 | S41: 0 | T41: 0 | U41: 0 | V41: =W41/2500 -> 6 | W41: 15000 | X41: 15 | Y41: 0 | Z41: 0 | AA41: 0 | AB41: 0 | AC41: 0 | AD41: 0 | AE41: 0 | AF41: 0 | AG41: 0 | AH41: 0 | AI41: 0 | AJ41: 0 | AK41: 0 | AL41: 0 | AM41: 0 | AN41: 0 | AO41: 0 | AP41: 0 | AQ41: =G41+J41+M41+P41+S41+V41+Y41+AB41+AE41+AH41+AK41+AN41 -> 12 | AR41: =H41+K41+N41+Q41+T41+W41+Z41+AC41+AF41+AI41+AL41+AO41 -> 30000 | AS41: 15
A42: 39 | B42: CHIMALTENANGO | C42: TECPÁN GUATEMALA | E42: 10 | F42: =E42*2500 -> 25000 | G42: 0 | H42: 0 | I42: 0 | J42: 0 | K42: 0 | L42: 0 | M42: 3.2 | N42: 8000 | O42: 8 | P42: =Q42/2500 -> 1.6 | Q42: =R42*1000 -> 4000 | R42: 4 | S42: 0 | T42: 0 | U42: 0 | V42: =W42/2500 -> 4.4 | W42: 11000 | X42: 11 | Y42: 0 | Z42: 0 | AA42: 0 | AB42: 0 | AC42: 0 | AD42: 0 | AE42: 0 | AF42: 0 | AG42: 0 | AH42: 0 | AI42: 0 | AJ42: 0 | AK42: 0 | AL42: 0 | AM42: 0 | AN42: 0 | AO42: 0 | AP42: 0 | AQ42: =G42+J42+M42+P42+S42+V42+Y42+AB42+AE42+AH42+AK42+AN42 -> 9.2 | AR42: =H42+K42+N42+Q42+T42+W42+Z42+AC42+AF42+AI42+AL42+AO42 -> 23000 | AS42: 12
A43: 40 | B43: CHIMALTENANGO | C43: YEPOCAPA | E43: 16.8 | F43: =E43*2500 -> 42000 | G43: 0 | H43: 0 | I43: 0 | J43: 0 | K43: 0 | L43: 0 | M43: 5.2 | N43: 13000 | O43: 13 | P43: =Q43/2500 -> 1.6 | Q43: =R43*1000 -> 4000 | R43: 4 | S43: 0 | T43: 0 | U43: 0 | V43: =W43/2500 -> 6.8 | W43: 17000 | X43: 17 | Y43: 0 | Z43: 0 | AA43: 0 | AB43: 0 | AC43: 0 | AD43: 0 | AE43: 0 | AF43: 0 | AG43: 0 | AH43: 0 | AI43: 0 | AJ43: 0 | AK43: 0 | AL43: 0 | AM43: 0 | AN43: 0 | AO43: 0 | AP43: 0 | AQ43: =G43+J43+M43+P43+S43+V43+Y43+AB43+AE43+AH43+AK43+AN43 -> 13.6 | AR43: =H43+K43+N43+Q43+T43+W43+Z43+AC43+AF43+AI43+AL43+AO43 -> 34000 | AS43: 17
A44: 41 | B44: CHIMALTENANGO | C44: ZARAGOZA | E44: 11.8 | F44: =E44*2500 -> 29500 | G44: 0 | H44: 0 | I44: 0 | J44: 0 | K44: 0 | L44: 0 | M44: 2.4 | N44: 6000 | O44: 6 | P44: =Q44/2500 -> 1.6 | Q44: =R44*1000 -> 4000 | R44: 4 | S44: 0 | T44: 0 | U44: 0 | V44: =W44/2500 -> 4 | W44: 10000 | X44: 10 | Y44: 0 | Z44: 0 | AA44: 0 | AB44: 0 | AC44: 0 | AD44: 0 | AE44: 0 | AF44: 0 | AG44: 0 | AH44: 0 | AI44: 0 | AJ44: 0 | AK44: 0 | AL44: 0 | AM44: 0 | AN44: 0 | AO44: 0 | AP44: 0 | AQ44: =G44+J44+M44+P44+S44+V44+Y44+AB44+AE44+AH44+AK44+AN44 -> 8 | AR44: =H44+K44+N44+Q44+T44+W44+Z44+AC44+AF44+AI44+AL44+AO44 -> 20000 | AS44: 10
A45: 42 | B45: CHIQUIMULA | C45: CAMOTÁN | E45: 35.8 | F45: =E45*2500 -> 89500 | G45: 0 | H45: 0 | I45: 0 | J45: 0 | K45: 0 | L45: 0 | M45: 15.2 | N45: 38000 | O45: 38 | P45: =Q45/2500 -> 2 | Q45: =R45*1000 -> 5000 | R45: 5 | S45: 0 | T45: 0 | U45: 0 | V45: =W45/2500 -> 16.8 | W45: 42000 | X45: 42 | Y45: 0 | Z45: 0 | AA45: 0 | AB45: 0 | AC45: 0 | AD45: 0 | AE45: 0 | AF45: 0 | AG45: 0 | AH45: 0 | AI45: 0 | AJ45: 0 | AK45: 0 | AL45: 0 | AM45: 0 | AN45: 0 | AO45: 0 | AP45: 0 | AQ45: =G45+J45+M45+P45+S45+V45+Y45+AB45+AE45+AH45+AK45+AN45 -> 34 | AR45: =H45+K45+N45+Q45+T45+W45+Z45+AC45+AF45+AI45+AL45+AO45 -> 85000 | AS45: 43
A46: 43 | B46: CHIQUIMULA | C46: CHIQUIMULA | E46: 41 | F46: =E46*2500 -> 102500 | G46: 0 | H46: 0 | I46: 0 | J46: 0 | K46: 0 | L46: 0 | M46: 11.6 | N46: 29000 | O46: 29 | P46: =Q46/2500 -> 6.8 | Q46: =R46*1000 -> 17000 | R46: 17 | S46: 0 | T46: 0 | U46: 0 | V46: =W46/2500 -> 18.8 | W46: 47000 | X46: 47 | Y46: 0 | Z46: 0 | AA46: 0 | AB46: 0 | AC46: 0 | AD46: 0 | AE46: 0 | AF46: 0 | AG46: 0 | AH46: 0 | AI46: 0 | AJ46: 0 | AK46: 0 | AL46: 0 | AM46: 0 | AN46: 0 | AO46: 0 | AP46: 0 | AQ46: =G46+J46+M46+P46+S46+V46+Y46+AB46+AE46+AH46+AK46+AN46 -> 37.2 | AR46: =H46+K46+N46+Q46+T46+W46+Z46+AC46+AF46+AI46+AL46+AO46 -> 93000 | AS46: 47
...

Sheet BECA SUPERIOR
A1: PROGRAMA SOCIAL "BECA EDUCACIÓN SUPERIOR"
A2: NO. | B2: DEPARTAMENTO | C2: MUNICIPIO | D2: UNIDAD DE MEDIDA | E2: PLANIFICACIÓN | G2: EJECUCIÓN 30 ENERO | J2: EJECUCIÓN 28 FEBRERO | M2: EJECUCIÓN 31 MARZO | P2: EJECUCIÓN 30 ABRIL | S2: EJECUCIÓN 31 MAYO | V2: EJECUCIÓN 30 JUNIO | Y2: EJECUCIÓN 31 JULIO | AB2: EJECUCIÓN 31 AGOSTO | AE2: EJECUCIÓN 30 SEPTIEMBRE | AH2: EJECUCIÓN 31 OCTUBRE | AK2: EJECUCIÓN 30 NOVIEMBRE | AN2: EJECUCIÓN 31 DICIEMBRE | AQ2: EJECUCIÓN TOTAL 2026
E3: FÍSICA | F3: FINANCIERA | G3: FÍSICA | H3: FINANCIERA | I3: Beneficiarios | J3: FÍSICA | K3: FINANCIERA | L3: Beneficiarios | M3: FÍSICA | N3: FINANCIERA | O3: Beneficiarios | P3: FÍSICA | Q3: FINANCIERA | R3: Beneficiarios | S3: FÍSICA | T3: FINANCIERA | U3: Beneficiarios | V3: FÍSICA | W3: FINANCIERA | X3: Beneficiarios | Y3: FÍSICA | Z3: FINANCIERA | AA3: Beneficiarios | AB3: FÍSICA | AC3: FINANCIERA | AD3: Beneficiarios | AE3: FÍSICA | AF3: FINANCIERA | AG3: Beneficiarios | AH3: FÍSICA | AI3: FINANCIERA | AJ3: Beneficiarios | AK3: FÍSICA | AL3: FINANCIERA | AM3: Beneficiarios | AN3: FÍSICA | AO3: FINANCIERA | AP3: Beneficiarios | AQ3: FÍSICA | AR3: FINANCIERA | AS3: Beneficiarios
A4: 1 | B4: ALTA VERAPAZ | C4: CAHABÓN | D4: Beca | P4: =Q4/2500 -> 8.64 | Q4: =R4*1800 -> 21600 | R4: 12 | S4: 0 | T4: 0 | U4: 0 | V4: 0 | W4: 0 | X4: 0 | Y4: 0 | Z4: 0 | AA4: 0 | AB4: 0 | AC4: 0 | AD4: 0 | AE4: 0 | AF4: 0 | AG4: 0 | AH4: 0 | AI4: 0 | AJ4: 0 | AK4: 0 | AL4: 0 | AM4: 0 | AN4: 0 | AO4: 0 | AP4: 0 | AQ4: =AR4/2500 -> 8.64 | AR4: =AS4*1800 -> 21600 | AS4: 12
A5: 2 | B5: ALTA VERAPAZ | C5: CHAHAL | P5: =Q5/2500 -> 0 | Q5: =R5*1800 -> 0 | R5: 0 | S5: 0 | T5: 0 | U5: 0 | V5: 0 | W5: 0 | X5: 0 | Y5: 0 | Z5: 0 | AA5: 0 | AB5: 0 | AC5: 0 | AD5: 0 | AE5: 0 | AF5: 0 | AG5: 0 | AH5: 0 | AI5: 0 | AJ5: 0 | AK5: 0 | AL5: 0 | AM5: 0 | AN5: 0 | AO5: 0 | AP5: 0 | AQ5: =AR5/2500 -> 0 | AR5: =AS5*1800 -> 0 | AS5: 0
A6: 3 | B6: ALTA VERAPAZ | C6: CHISEC | P6: =Q6/2500 -> 0 | Q6: =R6*1800 -> 0 | R6: 0 | S6: 0 | T6: 0 | U6: 0 | V6: 0 | W6: 0 | X6: 0 | Y6: 0 | Z6: 0 | AA6: 0 | AB6: 0 | AC6: 0 | AD6: 0 | AE6: 0 | AF6: 0 | AG6: 0 | AH6: 0 | AI6: 0 | AJ6: 0 | AK6: 0 | AL6: 0 | AM6: 0 | AN6: 0 | AO6: 0 | AP6: 0 | AQ6: =AR6/2500 -> 0 | AR6: =AS6*1800 -> 0 | AS6: 0
A7: 4 | B7: ALTA VERAPAZ | C7: COBÁN | P7: =Q7/2500 -> 10.08 | Q7: =R7*1800 -> 25200 | R7: 14 | S7: 0 | T7: 0 | U7: 0 | V7: 0 | W7: 0 | X7: 0 | Y7: 0 | Z7: 0 | AA7: 0 | AB7: 0 | AC7: 0 | AD7: 0 | AE7: 0 | AF7: 0 | AG7: 0 | AH7: 0 | AI7: 0 | AJ7: 0 | AK7: 0 | AL7: 0 | AM7: 0 | AN7: 0 | AO7: 0 | AP7: 0 | AQ7: =AR7/2500 -> 10.08 | AR7: =AS7*1800 -> 25200 | AS7: 14
A8: 5 | B8: ALTA VERAPAZ | C8: FRAY BARTOLOMÉ DE LAS CASAS | P8: =Q8/2500 -> 0 | Q8: =R8*1800 -> 0 | R8: 0 | S8: 0 | T8: 0 | U8: 0 | V8: 0 | W8: 0 | X8: 0 | Y8: 0 | Z8: 0 | AA8: 0 | AB8: 0 | AC8: 0 | AD8: 0 | AE8: 0 | AF8: 0 | AG8: 0 | AH8: 0 | AI8: 0 | AJ8: 0 | AK8: 0 | AL8: 0 | AM8: 0 | AN8: 0 | AO8: 0 | AP8: 0 | AQ8: =AR8/2500 -> 0 | AR8: =AS8*1800 -> 0 | AS8: 0
A9: 6 | B9: ALTA VERAPAZ | C9: LANQUÍN | P9: =Q9/2500 -> 5.04 | Q9: =R9*1800 -> 12600 | R9: 7 | S9: 0 | T9: 0 | U9: 0 | V9: 0 | W9: 0 | X9: 0 | Y9: 0 | Z9: 0 | AA9: 0 | AB9: 0 | AC9: 0 | AD9: 0 | AE9: 0 | AF9: 0 | AG9: 0 | AH9: 0 | AI9: 0 | AJ9: 0 | AK9: 0 | AL9: 0 | AM9: 0 | AN9: 0 | AO9: 0 | AP9: 0 | AQ9: =AR9/2500 -> 5.04 | AR9: =AS9*1800 -> 12600 | AS9: 7
A10: 7 | B10: ALTA VERAPAZ | C10: PANZÓS | P10: =Q10/2500 -> 0 | Q10: =R10*1800 -> 0 | R10: 0 | S10: 0 | T10: 0 | U10: 0 | V10: 0 | W10: 0 | X10: 0 | Y10: 0 | Z10: 0 | AA10: 0 | AB10: 0 | AC10: 0 | AD10: 0 | AE10: 0 | AF10: 0 | AG10: 0 | AH10: 0 | AI10: 0 | AJ10: 0 | AK10: 0 | AL10: 0 | AM10: 0 | AN10: 0 | AO10: 0 | AP10: 0 | AQ10: =AR10/2500 -> 0 | AR10: =AS10*1800 -> 0 | AS10: 0
A11: 8 | B11: ALTA VERAPAZ | C11: RAXRUHÁ | P11: =Q11/2500 -> 0 | Q11: =R11*1800 -> 0 | R11: 0 | S11: 0 | T11: 0 | U11: 0 | V11: 0 | W11: 0 | X11: 0 | Y11: 0 | Z11: 0 | AA11: 0 | AB11: 0 | AC11: 0 | AD11: 0 | AE11: 0 | AF11: 0 | AG11: 0 | AH11: 0 | AI11: 0 | AJ11: 0 | AK11: 0 | AL11: 0 | AM11: 0 | AN11: 0 | AO11: 0 | AP11: 0 | AQ11: =AR11/2500 -> 0 | AR11: =AS11*1800 -> 0 | AS11: 0
A12: 9 | B12: ALTA VERAPAZ | C12: SAN CRISTÓBAL VERAPAZ | P12: =Q12/2500 -> 2.16 | Q12: =R12*1800 -> 5400 | R12: 3 | S12: 0 | T12: 0 | U12: 0 | V12: 0 | W12: 0 | X12: 0 | Y12: 0 | Z12: 0 | AA12: 0 | AB12: 0 | AC12: 0 | AD12: 0 | AE12: 0 | AF12: 0 | AG12: 0 | AH12: 0 | AI12: 0 | AJ12: 0 | AK12: 0 | AL12: 0 | AM12: 0 | AN12: 0 | AO12: 0 | AP12: 0 | AQ12: =AR12/2500 -> 2.16 | AR12: =AS12*1800 -> 5400 | AS12: 3
A13: 10 | B13: ALTA VERAPAZ | C13: SAN JUAN CHAMELCO | P13: =Q13/2500 -> 0 | Q13: =R13*1800 -> 0 | R13: 0 | S13: 0 | T13: 0 | U13: 0 | V13: 0 | W13: 0 | X13: 0 | Y13: 0 | Z13: 0 | AA13: 0 | AB13: 0 | AC13: 0 | AD13: 0 | AE13: 0 | AF13: 0 | AG13: 0 | AH13: 0 | AI13: 0 | AJ13: 0 | AK13: 0 | AL13: 0 | AM13: 0 | AN13: 0 | AO13: 0 | AP13: 0 | AQ13: =AR13/2500 -> 0 | AR13: =AS13*1800 -> 0 | AS13: 0
A14: 11 | B14: ALTA VERAPAZ | C14: SAN PEDRO CARCHÁ | P14: =Q14/2500 -> 0.72 | Q14: =R14*1800 -> 1800 | R14: 1 | S14: 0 | T14: 0 | U14: 0 | V14: 0 | W14: 0 | X14: 0 | Y14: 0 | Z14: 0 | AA14: 0 | AB14: 0 | AC14: 0 | AD14: 0 | AE14: 0 | AF14: 0 | AG14: 0 | AH14: 0 | AI14: 0 | AJ14: 0 | AK14: 0 | AL14: 0 | AM14: 0 | AN14: 0 | AO14: 0 | AP14: 0 | AQ14: =AR14/2500 -> 0.72 | AR14: =AS14*1800 -> 1800 | AS14: 1
A15: 12 | B15: ALTA VERAPAZ | C15: SANTA CATALINA LA TINTA | P15: =Q15/2500 -> 0 | Q15: =R15*1800 -> 0 | R15: 0 | S15: 0 | T15: 0 | U15: 0 | V15: 0 | W15: 0 | X15: 0 | Y15: 0 | Z15: 0 | AA15: 0 | AB15: 0 | AC15: 0 | AD15: 0 | AE15: 0 | AF15: 0 | AG15: 0 | AH15: 0 | AI15: 0 | AJ15: 0 | AK15: 0 | AL15: 0 | AM15: 0 | AN15: 0 | AO15: 0 | AP15: 0 | AQ15: =AR15/2500 -> 0 | AR15: =AS15*1800 -> 0 | AS15: 0
A16: 13 | B16: ALTA VERAPAZ | C16: SANTA CRUZ VERAPAZ | P16: =Q16/2500 -> 2.16 | Q16: =R16*1800 -> 5400 | R16: 3 | S16: 0 | T16: 0 | U16: 0 | V16: 0 | W16: 0 | X16: 0 | Y16: 0 | Z16: 0 | AA16: 0 | AB16: 0 | AC16: 0 | AD16: 0 | AE16: 0 | AF16: 0 | AG16: 0 | AH16: 0 | AI16: 0 | AJ16: 0 | AK16: 0 | AL16: 0 | AM16: 0 | AN16: 0 | AO16: 0 | AP16: 0 | AQ16: =AR16/2500 -> 2.16 | AR16: =AS16*1800 -> 5400 | AS16: 3
... A20: 17 | B20: ALTA VERAPAZ | C20: TUCURÚ | P20: =Q20/2500 -> 0 | Q20: =R20*1800 -> 0 | R20: 0 | S20: 0 | T20: 0 | U20: 0 | V20: 0 | W20: 0 | X20: 0 | Y20: 0 | Z20: 0 | AA20: 0 | AB20: 0 | AC20: 0 | AD20: 0 | AE20: 0 | AF20: 0 | AG20: 0 | AH20: 0 | AI20: 0 | AJ20: 0 | AK20: 0 | AL20: 0 | AM20: 0 | AN20: 0 | AO20: 0 | AP20: 0 | AQ20: =AR20/2500 -> 0 | AR20: =AS20*1800 -> 0 | AS20: 0
A21: 18 | B21: BAJA VERAPAZ | C21: CUBULCO | D21: Beca | P21: =Q21/2500 -> 5.04 | Q21: =R21*1800 -> 12600 | R21: 7 | S21: 0 | T21: 0 | U21: 0 | V21: 0 | W21: 0 | X21: 0 | Y21: 0 | Z21: 0 | AA21: 0 | AB21: 0 | AC21: 0 | AD21: 0 | AE21: 0 | AF21: 0 | AG21: 0 | AH21: 0 | AI21: 0 | AJ21: 0 | AK21: 0 | AL21: 0 | AM21: 0 | AN21: 0 | AO21: 0 | AP21: 0 | AQ21: =AR21/2500 -> 5.04 | AR21: =AS21*1800 -> 12600 | AS21: 7
A22: 19 | B22: BAJA VERAPAZ | C22: EL CHOL | P22: =Q22/2500 -> 5.76 | Q22: =R22*1800 -> 14400 | R22: 8 | S22: 0 | T22: 0 | U22: 0 | V22: 0 | W22: 0 | X22: 0 | Y22: 0 | Z22: 0 | AA22: 0 | AB22: 0 | AC22: 0 | AD22: 0 | AE22: 0 | AF22: 0 | AG22: 0 | AH22: 0 | AI22: 0 | AJ22: 0 | AK22: 0 | AL22: 0 | AM22: 0 | AN22: 0 | AO22: 0 | AP22: 0 | AQ22: =AR22/2500 -> 5.76 | AR22: =AS22*1800 -> 14400 | AS22: 8
A23: 20 | B23: BAJA VERAPAZ | C23: GRANADOS | P23: =Q23/2500 -> 8.64 | Q23: =R23*1800 -> 21600 | R23: 12 | S23: 0 | T23: 0 | U23: 0 | V23: 0 | W23: 0 | X23: 0 | Y23: 0 | Z23: 0 | AA23: 0 | AB23: 0 | AC23: 0 | AD23: 0 | AE23: 0 | AF23: 0 | AG23: 0 | AH23: 0 | AI23: 0 | AJ23: 0 | AK23: 0 | AL23: 0 | AM23: 0 | AN23: 0 | AO23: 0 | AP23: 0 | AQ23: =AR23/2500 -> 8.64 | AR23: =AS23*1800 -> 21600 | AS23: 12
A24: 21 | B24: BAJA VERAPAZ | C24: PURULHÁ | P24: =Q24/2500 -> 7.92 | Q24: =R24*1800 -> 19800 | R24: 11 | S24: 0 | T24: 0 | U24: 0 | V24: 0 | W24: 0 | X24: 0 | Y24: 0 | Z24: 0 | AA24: 0 | AB24: 0 | AC24: 0 | AD24: 0 | AE24: 0 | AF24: 0 | AG24: 0 | AH24: 0 | AI24: 0 | AJ24: 0 | AK24: 0 | AL24: 0 | AM24: 0 | AN24: 0 | AO24: 0 | AP24: 0 | AQ24: =AR24/2500 -> 7.92 | AR24: =AS24*1800 -> 19800 | AS24: 11
A25: 22 | B25: BAJA VERAPAZ | C25: RABINAL | P25: =Q25/2500 -> 1.44 | Q25: =R25*1800 -> 3600 | R25: 2 | S25: 0 | T25: 0 | U25: 0 | V25: 0 | W25: 0 | X25: 0 | Y25: 0 | Z25: 0 | AA25: 0 | AB25: 0 | AC25: 0 | AD25: 0 | AE25: 0 | AF25: 0 | AG25: 0 | AH25: 0 | AI25: 0 | AJ25: 0 | AK25: 0 | AL25: 0 | AM25: 0 | AN25: 0 | AO25: 0 | AP25: 0 | AQ25: =AR25/2500 -> 1.44 | AR25: =AS25*1800 -> 3600 | AS25: 2
A26: 23 | B26: BAJA VERAPAZ | C26: SALAMÁ | P26: =Q26/2500 -> 6.48 | Q26: =R26*1800 -> 16200 | R26: 9 | S26: 0 | T26: 0 | U26: 0 | V26: 0 | W26: 0 | X26: 0 | Y26: 0 | Z26: 0 | AA26: 0 | AB26: 0 | AC26: 0 | AD26: 0 | AE26: 0 | AF26: 0 | AG26: 0 | AH26: 0 | AI26: 0 | AJ26: 0 | AK26: 0 | AL26: 0 | AM26: 0 | AN26: 0 | AO26: 0 | AP26: 0 | AQ26: =AR26/2500 -> 6.48 | AR26: =AS26*1800 -> 16200 | AS26: 9
A27: 24 | B27: BAJA VERAPAZ | C27: SAN JERÓNIMO | P27: =Q27/2500 -> 4.32 | Q27: =R27*1800 -> 10800 | R27: 6 | S27: 0 | T27: 0 | U27: 0 | V27: 0 | W27: 0 | X27: 0 | Y27: 0 | Z27: 0 | AA27: 0 | AB27: 0 | AC27: 0 | AD27: 0 | AE27: 0 | AF27: 0 | AG27: 0 | AH27: 0 | AI27: 0 | AJ27: 0 | AK27: 0 | AL27: 0 | AM27: 0 | AN27: 0 | AO27: 0 | AP27: 0 | AQ27: =AR27/2500 -> 4.32 | AR27: =AS27*1800 -> 10800 | AS27: 6
A28: 25 | B28: BAJA VERAPAZ | C28: SAN MIGUEL CHICAJ | P28: =Q28/2500 -> 3.6 | Q28: =R28*1800 -> 9000 | R28: 5 | S28: 0 | T28: 0 | U28: 0 | V28: 0 | W28: 0 | X28: 0 | Y28: 0 | Z28: 0 | AA28: 0 | AB28: 0 | AC28: 0 | AD28: 0 | AE28: 0 | AF28: 0 | AG28: 0 | AH28: 0 | AI28: 0 | AJ28: 0 | AK28: 0 | AL28: 0 | AM28: 0 | AN28: 0 | AO28: 0 | AP28: 0 | AQ28: =AR28/2500 -> 3.6 | AR28: =AS28*1800 -> 9000 | AS28: 5
A29: 26 | B29: CHIMALTENANGO | C29: ACATENANGO | P29: =Q29/2500 -> 1.44 | Q29: =R29*1800 -> 3600 | R29: 2 | S29: 0 | T29: 0 | U29: 0 | V29: 0 | W29: 0 | X29: 0 | Y29: 0 | Z29: 0 | AA29: 0 | AB29: 0 | AC29: 0 | AD29: 0 | AE29: 0 | AF29: 0 | AG29: 0 | AH29: 0 | AI29: 0 | AJ29: 0 | AK29: 0 | AL29: 0 | AM29: 0 | AN29: 0 | AO29: 0 | AP29: 0 | AQ29: =AR29/2500 -> 1.44 | AR29: =AS29*1800 -> 3600 | AS29: 2
A30: 27 | B30: CHIMALTENANGO | C30: CHIMALTENANGO | P30: =Q30/2500 -> 4.32 | Q30: =R30*1800 -> 10800 | R30: 6 | S30: 0 | T30: 0 | U30: 0 | V30: 0 | W30: 0 | X30: 0 | Y30: 0 | Z30: 0 | AA30: 0 | AB30: 0 | AC30: 0 | AD30: 0 | AE30: 0 | AF30: 0 | AG30: 0 | AH30: 0 | AI30: 0 | AJ30: 0 | AK30: 0 | AL30: 0 | AM30: 0 | AN30: 0 | AO30: 0 | AP30: 0 | AQ30: =AR30/2500 -> 4.32 | AR30: =AS30*1800 -> 10800 | AS30: 6
A31: 28 | B31: CHIMALTENANGO | C31: COMALAPA | P31: =Q31/2500 -> 6.48 | Q31: =R31*1800 -> 16200 | R31: 9 | S31: 0 | T31: 0 | U31: 0 | V31: 0 | W31: 0 | X31: 0 | Y31: 0 | Z31: 0 | AA31: 0 | AB31: 0 | AC31: 0 | AD31: 0 | AE31: 0 | AF31: 0 | AG31: 0 | AH31: 0 | AI31: 0 | AJ31: 0 | AK31: 0 | AL31: 0 | AM31: 0 | AN31: 0 | AO31: 0 | AP31: 0 | AQ31: =AR31/2500 -> 6.48 | AR31: =AS31*1800 -> 16200 | AS31: 9
A32: 29 | B32: CHIMALTENANGO | C32: EL TEJAR | P32: =Q32/2500 -> 2.16 | Q32: =R32*1800 -> 5400 | R32: 3 | S32: 0 | T32: 0 | U32: 0 | V32: 0 | W32: 0 | X32: 0 | Y32: 0 | Z32: 0 | AA32: 0 | AB32: 0 | AC32: 0 | AD32: 0 | AE32: 0 | AF32: 0 | AG32: 0 | AH32: 0 | AI32: 0 | AJ32: 0 | AK32: 0 | AL32: 0 | AM32: 0 | AN32: 0 | AO32: 0 | AP32: 0 | AQ32: =AR32/2500 -> 2.16 | AR32: =AS32*1800 -> 5400 | AS32: 3
A33: 30 | B33: CHIMALTENANGO | C33: PARRAMOS | P33: =Q33/2500 -> 2.16 | Q33: =R33*1800 -> 5400 | R33: 3 | S33: 0 | T33: 0 | U33: 0 | V33: 0 | W33: 0 | X33: 0 | Y33: 0 | Z33: 0 | AA33: 0 | AB33: 0 | AC33: 0 | AD33: 0 | AE33: 0 | AF33: 0 | AG33: 0 | AH33: 0 | AI33: 0 | AJ33: 0 | AK33: 0 | AL33: 0 | AM33: 0 | AN33: 0 | AO33: 0 | AP33: 0 | AQ33: =AR33/2500 -> 2.16 | AR33: =AS33*1800 -> 5400 | AS33: 3
... A37: 34 | B37: CHIMALTENANGO | C37: SAN ANDRÉS ITZAPA | P37: =Q37/2500 -> 1.44 | Q37: =R37*1800 -> 3600 | R37: 2 | S37: 0 | T37: 0 | U37: 0 | V37: 0 | W37: 0 | X37: 0 | Y37: 0 | Z37: 0 | AA37: 0 | AB37: 0 | AC37: 0 | AD37: 0 | AE37: 0 | AF37: 0 | AG37: 0 | AH37: 0 | AI37: 0 | AJ37: 0 | AK37: 0 | AL37: 0 | AM37: 0 | AN37: 0 | AO37: 0 | AP37: 0 | AQ37: =AR37/2500 -> 1.44 | AR37: =AS37*1800 -> 3600 | AS37: 2
A38: 35 | B38: CHIMALTENANGO | C38: SAN JOSÉ POAQUIL | D38: Beca | P38: =Q38/2500 -> 0.72 | Q38: =R38*1800 -> 1800 | R38: 1 | S38: 0 | T38: 0 | U38: 0 | V38: 0 | W38: 0 | X38: 0 | Y38: 0 | Z38: 0 | AA38: 0 | AB38: 0 | AC38: 0 | AD38: 0 | AE38: 0 | AF38: 0 | AG38: 0 | AH38: 0 | AI38: 0 | AJ38: 0 | AK38: 0 | AL38: 0 | AM38: 0 | AN38: 0 | AO38: 0 | AP38: 0 | AQ38: =AR38/2500 -> 0.72 | AR38: =AS38*1800 -> 1800 | AS38: 1
A39: 36 | B39: CHIMALTENANGO | C39: SAN MARTÍN JILOTEPEQUE | P39: =Q39/2500 -> 0 | Q39: =R39*1800 -> 0 | S39: 0 | T39: 0 | U39: 0 | V39: 0 | W39: 0 | X39: 0 | Y39: 0 | Z39: 0 | AA39: 0 | AB39: 0 | AC39: 0 | AD39: 0 | AE39: 0 | AF39: 0 | AG39: 0 | AH39: 0 | AI39: 0 | AJ39: 0 | AK39: 0 | AL39: 0 | AM39: 0 | AN39: 0 | AO39: 0 | AP39: 0 | AQ39: =AR39/2500 -> 0 | AR39: =AS39*1800 -> 0
A40: 37 | B40: CHIMALTENANGO | C40: SANTA APOLONIA | P40: =Q40/2500 -> 0.72 | Q40: =R40*1800 -> 1800 | R40: 1 | S40: 0 | T40: 0 | U40: 0 | V40: 0 | W40: 0 | X40: 0 | Y40: 0 | Z40: 0 | AA40: 0 | AB40: 0 | AC40: 0 | AD40: 0 | AE40: 0 | AF40: 0 | AG40: 0 | AH40: 0 | AI40: 0 | AJ40: 0 | AK40: 0 | AL40: 0 | AM40: 0 | AN40: 0 | AO40: 0 | AP40: 0 | AQ40: =AR40/2500 -> 0.72 | AR40: =AS40*1800 -> 1800 | AS40: 1
A41: 38 | B41: CHIMALTENANGO | C41: SANTA CRUZ BALANYÁ | P41: =Q41/2500 -> 1.44 | Q41: =R41*1800 -> 3600 | R41: 2 | S41: 0 | T41: 0 | U41: 0 | V41: 0 | W41: 0 | X41: 0 | Y41: 0 | Z41: 0 | AA41: 0 | AB41: 0 | AC41: 0 | AD41: 0 | AE41: 0 | AF41: 0 | AG41: 0 | AH41: 0 | AI41: 0 | AJ41: 0 | AK41: 0 | AL41: 0 | AM41: 0 | AN41: 0 | AO41: 0 | AP41: 0 | AQ41: =AR41/2500 -> 1.44 | AR41: =AS41*1800 -> 3600 | AS41: 2
A42: 39 | B42: CHIMALTENANGO | C42: TECPÁN GUATEMALA | P42: =Q42/2500 -> 2.16 | Q42: =R42*1800 -> 5400 | R42: 3 | S42: 0 | T42: 0 | U42: 0 | V42: 0 | W42: 0 | X42: 0 | Y42: 0 | Z42: 0 | AA42: 0 | AB42: 0 | AC42: 0 | AD42: 0 | AE42: 0 | AF42: 0 | AG42: 0 | AH42: 0 | AI42: 0 | AJ42: 0 | AK42: 0 | AL42: 0 | AM42: 0 | AN42: 0 | AO42: 0 | AP42: 0 | AQ42: =AR42/2500 -> 2.16 | AR42: =AS42*1800 -> 5400 | AS42: 3
A43: 40 | B43: CHIMALTENANGO | C43: YEPOCAPA | P43: =Q43/2500 -> 0 | Q43: =R43*1800 -> 0 | R43: 0 | S43: 0 | T43: 0 | U43: 0 | V43: 0 | W43: 0 | X43: 0 | Y43: 0 | Z43: 0 | AA43: 0 | AB43: 0 | AC43: 0 | AD43: 0 | AE43: 0 | AF43: 0 | AG43: 0 | AH43: 0 | AI43: 0 | AJ43: 0 | AK43: 0 | AL43: 0 | AM43: 0 | AN43: 0 | AO43: 0 | AP43: 0 | AQ43: =AR43/2500 -> 0 | AR43: =AS43*1800 -> 0 | AS43: 0
A44: 41 | B44: CHIMALTENANGO | C44: ZARAGOZA | P44: =Q44/2500 -> 3.6 | Q44: =R44*1800 -> 9000 | R44: 5 | S44: 0 | T44: 0 | U44: 0 | V44: 0 | W44: 0 | X44: 0 | Y44: 0 | Z44: 0 | AA44: 0 | AB44: 0 | AC44: 0 | AD44: 0 | AE44: 0 | AF44: 0 | AG44: 0 | AH44: 0 | AI44: 0 | AJ44: 0 | AK44: 0 | AL44: 0 | AM44: 0 | AN44: 0 | AO44: 0 | AP44: 0 | AQ44: =AR44/2500 -> 3.6 | AR44: =AS44*1800 -> 9000 | AS44: 5
A45: 42 | B45: CHIQUIMULA | C45: CAMOTÁN | P45: =Q45/2500 -> 0.72 | Q45: =R45*1800 -> 1800 | R45: 1 | S45: 0 | T45: 0 | U45: 0 | V45: 0 | W45: 0 | X45: 0 | Y45: 0 | Z45: 0 | AA45: 0 | AB45: 0 | AC45: 0 | AD45: 0 | AE45: 0 | AF45: 0 | AG45: 0 | AH45: 0 | AI45: 0 | AJ45: 0 | AK45: 0 | AL45: 0 | AM45: 0 | AN45: 0 | AO45: 0 | AP45: 0 | AQ45: =AR45/2500 -> 0.72 | AR45: =AS45*1800 -> 1800 | AS45: 1
A46: 43 | B46: CHIQUIMULA | C46: CHIQUIMULA | P46: =Q46/2500 -> 8.64 | Q46: =R46*1800 -> 21600 | R46: 12 | S46: 0 | T46: 0 | U46: 0 | V46: 0 | W46: 0 | X46: 0 | Y46: 0 | Z46: 0 | AA46: 0 | AB46: 0 | AC46: 0 | AD46: 0 | AE46: 0 | AF46: 0 | AG46: 0 | AH46: 0 | AI46: 0 | AJ46: 0 | AK46: 0 | AL46: 0 | AM46: 0 | AN46: 0 | AO46: 0 | AP46: 0 | AQ46: =AR46/2500 -> 8.64 | AR46: =AS46*1800 -> 21600 | AS46: 12
...

Sheet JOVENES PROTAGONISTAS
A2: PROGRAMA SOCIAL "JÓVENES PROTAGONISTAS" | V2: =+H146 -> 0 | Y2: =476985.41+34720 -> 511705.41
A3: NO. | B3: DEPARTAMENTO | C3: MUNICIPIO | D3: UNIDAD DE MEDIDA | E3: EJECUCIÓN 30 ENERO | G3: EJECUCIÓN 28 FEBRERO | I3: EJECUCIÓN 31 DE MARZO | K3: EJECUCIÓN 30 DE ABRIL | M3: EJECUCIÓN 31 DE MAYO | O3: EJECUCIÓN 30 DE JUNIO | Q3: EJECUCIÓN 31 DE JULIO | S3: EJECUCIÓN TOTAL 2026 | V3: 3872299.4 | X3: 1794116.5 | Y3: =+Y2/5092 -> 100.49203 | Z3: 1459509.5 | AA3: 2566297.1
E4: FÍSICA | F4: FINANCIERA | G4: FÍSICA | H4: FINANCIERA | I4: FÍSICA | J4: FINANCIERA | K4: FÍSICA | L4: FINANCIERA | M4: FÍSICA | N4: FINANCIERA | O4: FÍSICA | P4: FINANCIERA | Q4: FÍSICA | R4: FINANCIERA | S4: FÍSICA | T4: FINANCIERA | V4: =+V3/4899 -> 790.42649 | X4: =+X3/1779 -> 1008.4972 | Y4: =+Y3 -> 100.49203 | Z4: =+Z3/I133 -> 165.75917 | AA4: =+AA3/11160 -> 229.95494
A5: 1 | B5: Guatemala | C5: San Juan Sacatepéquez | D5: Persona | E5: 0 | F5: 0 | G5: 280 | H5: =+G5*Y5 -> 28137.768 | I5: 275 | J5: =+I5*Z5 -> 45583.772 | K5: 29 | L5: 24931.105 | M5: 28 | N5: =+M5*X5 -> 28237.921 | O5: 268 | P5: =+O5*AA5 -> 61627.923 | Q5: 102 | R5: =+Q5*V5 -> 80623.502 | S5: =+G5+I5+K5+M5+O5+Q5 -> 982 | T5: =+H5+J5+L5+N5+P5+R5 -> 269141.99 | V5: =+V4 -> 790.42649 | X5: =+X4 -> 1008.4972 | Y5: =+Y4 -> 100.49203 | Z5: =+Z4 -> 165.75917 | AA5: =+AA4 -> 229.95494
A6: =+A5+1 -> 2 | C6: San Raymundo | E6: 0 | F6: 0 | G6: 130 | H6: =+G6*Y5 -> 13063.964 | I6: 174 | J6: =+I6*Z6 -> 28842.096 | K6: 38 | L6: 32668.345 | M6: 14 | N6: =+M6*X6 -> 14118.961 | O6: 134 | P6: =+O6*AA6 -> 30813.962 | Q6: 42 | R6: =+Q6*V6 -> 33197.912 | S6: =+G6+I6+K6+M6+O6+Q6 -> 532 | T6: =+H6+J6+L6+N6+P6+R6 -> 152705.24 | V6: =+V5 -> 790.42649 | W6: =+W5 -> 0 | X6: =+X5 -> 1008.4972 | Y6: =+Y5 -> 100.49203 | Z6: =+Z5 -> 165.75917 | AA6: =+AA5 -> 229.95494
A7: =+A6+1 -> 3 | C7: Villa Nueva | E7: 0 | F7: 0 | G7: 354 | H7: =+G7*Y6 -> 35574.178 | I7: 373 | J7: =+I7*Z7 -> 61828.171 | K7: 39 | L7: 33528.038 | M7: 9 | N7: =+M7*X7 -> 9076.4747 | O7: 377 | P7: =+O7*AA7 -> 86693.012 | Q7: 202 | R7: =+Q7*V7 -> 159666.15 | S7: =+G7+I7+K7+M7+O7+Q7 -> 1354 | T7: =+H7+J7+L7+N7+P7+R7 -> 386366.02 | V7: =+V6 -> 790.42649 | W7: =+W6 -> 0 | X7: =+X6 -> 1008.4972 | Y7: =+Y6 -> 100.49203 | Z7: =+Z6 -> 165.75917 | AA7: =+AA6 -> 229.95494
A8: =+A7+1 -> 4 | C8: San Pedro Sacatepéquez | E8: 0 | F8: 0 | G8: 204 | H8: =+G8*Y7 -> 20500.374 | I8: 171 | J8: =+I8*Z8 -> 28344.818 | K8: 12 | L8: 10316.319 | M8: 5 | N8: =+M8*X8 -> 5042.4859 | O8: 123 | P8: =+O8*AA8 -> 28284.457 | Q8: 53 | R8: =+Q8*V8 -> 41892.604 | S8: =+G8+I8+K8+M8+O8+Q8 -> 568 | T8: =+H8+J8+L8+N8+P8+R8 -> 134381.06 | V8: =+V7 -> 790.42649 | W8: =+W7 -> 0 | X8: =+X7 -> 1008.4972 | Y8: =+Y7 -> 100.49203 | Z8: =+Z7 -> 165.75917 | AA8: =+AA7 -> 229.95494
A9: =+A8+1 -> 5 | C9: Mixco | E9: 0 | F9: 0 | G9: 108 | H9: =+G9*Y8 -> 10853.139 | I9: 167 | J9: =+I9*Z9 -> 27681.782 | K9: 15 | L9: 12895.399 | M9: 8 | N9: =+M9*X9 -> 8067.9775 | O9: 125 | P9: =+O9*AA9 -> 28744.367 | Q9: 11 | R9: =+Q9*V9 -> 8694.6914 | S9: =+G9+I9+K9+M9+O9+Q9 -> 434 | T9: =+H9+J9+L9+N9+P9+R9 -> 96937.356 | V9: =+V8 -> 790.42649 | W9: =+W8 -> 0 | X9: =+X8 -> 1008.4972 | Y9: =+Y8 -> 100.49203 | Z9: =+Z8 -> 165.75917 | AA9: =+AA8 -> 229.95494
A10: =+A9+1 -> 6 | C10: Guatemala | E10: 0 | F10: 0 | G10: 967 | H10: =+G10*Y9 -> 97175.792 | I10: 946 | J10: =+I10*Z10 -> 156808.18 | K10: 153 | L10: 131533.07 | M10: 247 | N10: =+M10*X10 -> 249098.81 | O10: 990 | P10: =+O10*AA10 -> 227655.39 | Q10: 463 | R10: =+Q10*V10 -> 365967.46 | S10: =+G10+I10+K10+M10+O10+Q10 -> 3766 | T10: =+H10+J10+L10+N10+P10+R10 -> 1228238.7 | V10: =+V9 -> 790.42649 | W10: =+W9 -> 0 | X10: =+X9 -> 1008.4972 | Y10: =+Y9 -> 100.49203 | Z10: =+Z9 -> 165.75917 | AA10: =+AA9 -> 229.95494
A11: =+A10+1 -> 7 | C11: Chinautla | E11: 0 | F11: 0 | G11: 0 | H11: 0 | I11: 0 | J11: 0 | K11: 0 | L11: 0 | M11: 0 | N11: =+M11*X11 -> 0 | O11: 4 | P11: =+O11*AA11 -> 919.81975 | Q11: 33 | R11: =+Q11*V11 -> 26084.074 | S11: =+G11+I11+K11+M11+O11+Q11 -> 37 | T11: =+H11+J11+L11+N11+P11+R11 -> 27003.894 | V11: =+V10 -> 790.42649 | W11: =+W10 -> 0 | X11: =+X10 -> 1008.4972 | AA11: =+AA10 -> 229.95494
A12: =+A11+1 -> 8 | B12: Petén | C12: San Benito | E12: 0 | F12: 0 | G12: 99 | H12: =+G12*Y10 -> 9948.7108 | I12: 93 | J12: =+I12*Z12 -> 15415.603 | K12: 20 | L12: 17193.866 | M12: 0 | N12: =+M12*X12 -> 0 | O12: 120 | P12: =+O12*AA12 -> 27594.593 | Q12: 0 | R12: =+Q12*V12 -> 0 | S12: =+G12+I12+K12+M12+O12+Q12 -> 332 | T12: =+H12+J12+L12+N12+P12+R12 -> 70152.772 | V12: =+V11 -> 790.42649 | W12: =+W11 -> 0 | X12: =+X11 -> 1008.4972 | Y12: =+Y10 -> 100.49203 | Z12: =+Z10 -> 165.75917 | AA12: =+AA11 -> 229.95494
A13: =+A12+1 -> 9 | C13: La Libertad | E13: 0 | F13: 0 | G13: 13 | H13: =+G13*Y12 -> 1306.3964 | I13: 7 | J13: =+I13*Z13 -> 1160.3142 | K13: 4 | L13: 3438.7731 | M13: 0 | N13: =+M13*X13 -> 0 | O13: 0 | P13: =+O13*AA13 -> 0 | Q13: 9 | R13: =+Q13*V13 -> 7113.8384 | S13: =+G13+I13+K13+M13+O13+Q13 -> 33 | T13: =+H13+J13+L13+N13+P13+R13 -> 13019.322 | V13: =+V12 -> 790.42649 | W13: =+W12 -> 0 | X13: =+X12 -> 1008.4972 | Y13: =+Y12 -> 100.49203 | Z13: =+Z12 -> 165.75917 | AA13: =+AA12 -> 229.95494
A14: =+A13+1 -> 10 | C14: Melchor de Mencos | E14: 0 | F14: 0 | G14: 101 | H14: =+G14*Y13 -> 10149.695 | I14: 94 | J14: =+I14*Z14 -> 15581.362 | K14: 0 | L14: 0 | M14: 0 | N14: =+M14*X14 -> 0 | O14: 120 | P14: =+O14*AA14 -> 27594.593 | Q14: 0 | R14: =+Q14*V14 -> 0 | S14: =+G14+I14+K14+M14+O14+Q14 -> 315 | T14: =+H14+J14+L14+N14+P14+R14 -> 53325.65 | V14: =+V13 -> 790.42649 | W14: =+W13 -> 0 | X14: =+X13 -> 1008.4972 | Y14: =+Y13 -> 100.49203 | Z14: =+Z13 -> 165.75917 | AA14: =+AA13 -> 229.95494
A15: =+A14+1 -> 11 | C15: Sayaxché | E15: 0 | F15: 0 | G15: 125 | H15: =+G15*Y14 -> 12561.504 | I15: 160 | J15: =+I15*Z15 -> 26521.467 | K15: 21 | L15: 18053.559 | M15: 0 | N15: =+M15*X15 -> 0 | O15: 120 | P15: =+O15*AA15 -> 27594.593 | Q15: 0 | R15: =+Q15*V15 -> 0 | S15: =+G15+I15+K15+M15+O15+Q15 -> 426 | T15: =+H15+J15+L15+N15+P15+R15 -> 84731.122 | V15: =+V14 -> 790.42649 | W15: =+W14 -> 0 | X15: =+X14 -> 1008.4972 | Y15: =+Y14 -> 100.49203 | Z15: =+Z14 -> 165.75917 | AA15: =+AA14 -> 229.95494
A16: =+A15+1 -> 12 | B16: Alta Verapaz | C16: Cobán | E16: 0 | F16: 0 | G16: 10 | H16: =+G16*Y15 -> 1004.9203 | I16: 150 | J16: =+I16*Z16 -> 24863.876 | K16: 3 | L16: 2579.0798 | M16: 7 | N16: =+M16*X16 -> 7059.4803 | O16: 6 | P16: =+O16*AA16 -> 1379.7296 | Q16: 3 | R16: =+Q16*V16 -> 2371.2795 | S16: =+G16+I16+K16+M16+O16+Q16 -> 179 | T16: =+H16+J16+L16+N16+P16+R16 -> 39258.365 | V16: =+V15 -> 790.42649 | W16: =+W15 -> 0 | X16: =+X15 -> 1008.4972 | Y16: =+Y15 -> 100.49203 | Z16: =+Z15 -> 165.75917 | AA16: =+AA15 -> 229.95494
A17: =+A16+1 -> 13 | C17: San Miguel Tucuru | E17: 0 | F17: 0 | G17: 0 | H17: 0 | I17: 39 | J17: =+I17*Z17 -> 6464.6077 | K17: 18 | L17: 15474.479 | M17: 10 | N17: =+M17*X17 -> 10084.972 | O17: 3 | P17: =+O17*AA17 -> 689.86481 | Q17: 5 | R17: =+Q17*V17 -> 3952.1324 | S17: =+G17+I17+K17+M17+O17+Q17 -> 75 | T17: =+H17+J17+L17+N17+P17+R17 -> 36666.056 | V17: =+V16 -> 790.42649 | W17: =+W16 -> 0 | X17: =+X16 -> 1008.4972 | Z17: =+Z16 -> 165.75917 | AA17: =+AA16 -> 229.95494
A18: =+A17+1 -> 14 | C18: San Cristóbal Verapaz | E18: 0 | F18: 0 | G18: 21 | H18: =+G18*Y16 -> 2110.3326 | I18: 95 | J18: =+I18*Z18 -> 15747.121 | K18: 0 | L18: 0 | M18: 13 | N18: =+M18*X18 -> 13110.463 | O18: 0 | P18: =+O18*AA18 -> 0 | Q18: 26 | R18: =+Q18*V18 -> 20551.089 | S18: =+G18+I18+K18+M18+O18+Q18 -> 155 | T18: =+H18+J18+L18+N18+P18+R18 -> 51519.006 | V18: =+V17 -> 790.42649 | W18: =+W17 -> 0 | X18: =+X17 -> 1008.4972 | Y18: =+Y16 -> 100.49203 | Z18: =+Z17 -> 165.75917 | AA18: =+AA17 -> 229.95494
A19: =+A18+1 -> 15 | C19: Tamahú | E19: 0 | F19: 0 | G19: 0 | H19: 0 | I19: 0 | J19: 0 | K19: 0 | L19: 0 | M19: 0 | N19: 0 | O19: 0 | P19: 0 | Q19: 1 | R19: =+Q19*V19 -> 790.42649 | S19: =+G19+I19+K19+M19+O19+Q19 -> 1 | T19: =+H19+J19+L19+N19+P19+R19 -> 790.42649 | V19: =+V18 -> 790.42649
A20: =+A19+1 -> 16 | C20: San Pedro Carchá | E20: 0 | F20: 0 | G20: 0 | H20: 0 | I20: 0 | J20: 0 | K20: 0 | L20: 0 | M20: 0 | N20: 0 | O20: 0 | P20: 0 | Q20: 1 | R20: =+Q20*V20 -> 790.42649 | S20: =+G20+I20+K20+M20+O20+Q20 -> 1 | T20: =+H20+J20+L20+N20+P20+R20 -> 790.42649 | V20: =+V19 -> 790.42649
A21: =+A20+1 -> 17 | C21: Tactic | E21: 0 | F21: 0 | G21: 0 | H21: 0 | I21: 0 | J21: 0 | K21: 0 | L21: 0 | M21: 0 | N21: 0 | O21: 0 | P21: 0 | Q21: 1 | R21: =+Q21*V21 -> 790.42649 | S21: =+G21+I21+K21+M21+O21+Q21 -> 1 | T21: =+H21+J21+L21+N21+P21+R21 -> 790.42649 | V21: =+V20 -> 790.42649
A22: =+A21+1 -> 18 | B22: Baja Verapaz | C22: Purulhá | E22: 0 | F22: 0 | G22: 4 | H22: =+G22*Y18 -> 401.96811 | I22: 20 | J22: =+I22*Z22 -> 3315.1834 | K22: 11 | L22: 9456.6261 | M22: 60 | N22: =+M22*X22 -> 60509.831 | O22: 35 | P22: =+O22*AA22 -> 8048.4228 | Q22: 25 | R22: =+Q22*V22 -> 19760.662 | S22: =+G22+I22+K22+M22+O22+Q22 -> 155 | T22: =+H22+J22+L22+N22+P22+R22 -> 101492.69 | V22: =+V21 -> 790.42649 | W22: =+W18 -> 0 | X22: =+X18 -> 1008.4972 | Y22: =+Y18 -> 100.49203 | Z22: =+Z18 -> 165.75917 | AA22: =+AA18 -> 229.95494
A23: =+A22+1 -> 19 | C23: Rabinal | E23: 0 | F23: 0 | G23: 0 | H23: 0 | I23: 36 | J23: =+I23*Z23 -> 5967.3302 | K23: 18 | L23: 15474.479 | M23: 9 | N23: =+M23*X23 -> 9076.4747 | O23: 134 | P23: =+O23*AA23 -> 30813.962 | Q23: 14 | R23: =+Q23*V23 -> 11065.971 | S23: =+G23+I23+K23+M23+O23+Q23 -> 211 | T23: =+H23+J23+L23+N23+P23+R23 -> 72398.216 | V23: =+V22 -> 790.42649 | W23: =+W22 -> 0 | X23: =+X22 -> 1008.4972 | Z23: =+Z22 -> 165.75917 | AA23: =+AA22 -> 229.95494
A24: =+A23+1 -> 20 | C24: Salamá | E24: 0 | F24: 0 | G24: 8 | H24: =+G24*Y22 -> 803.93623 | I24: 38 | J24: =+I24*Z24 -> 6298.8485 | K24: 8 | L24: 6877.5463 | M24: 0 | N24: =+M24*X24 -> 0 | O24: 22 | P24: =+O24*AA24 -> 5059.0086 | Q24: 16 | R24: =+Q24*V24 -> 12646.824 | S24: =+G24+I24+K24+M24+O24+Q24 -> 92 | T24: =+H24+J24+L24+N24+P24+R24 -> 31686.163 | V24: =+V23 -> 790.42649 | W24: =+W23 -> 0 | X24: =+X23 -> 1008.4972 | Y24: =+Y22 -> 100.49203 | Z24: =+Z23 -> 165.75917 | AA24: =+AA23 -> 229.95494
A25: =+A24+1 -> 21 | C25: San Jerónimo | E25: 0 | F25: 0 | G25: 0 | H25: 0 | I25: 0 | J25: 0 | K25: 0 | L25: 0 | M25: 0 | N25: 0 | O25: 0 | P25: 0 | Q25: 1 | R25: =+Q25*V25 -> 790.42649 | S25: =+G25+I25+K25+M25+O25+Q25 -> 1 | T25: =+H25+J25+L25+N25+P25+R25 -> 790.42649 | V25: =+V24 -> 790.42649
A26: =+A25+1 -> 22 | C26: San Miguel Chicaj | E26: 0 | F26: 0 | G26: 0 | H26: 0 | I26: 0 | J26: 0 | K26: 0 | L26: 0 | M26: 0 | N26: 0 | O26: 0 | P26: 0 | Q26: 4 | R26: =+Q26*V26 -> 3161.7059 | S26: =+G26+I26+K26+M26+O26+Q26 -> 4 | T26: =+H26+J26+L26+N26+P26+R26 -> 3161.7059 | V26: =+V25 -> 790.42649
A27: =+A26+1 -> 23 | B27: Izabal | C27: Livingston | E27: 0 | F27: 0 | G27: 52 | H27: =+G27*Y24 -> 5225.5855 | I27: 243 | J27: =+I27*Z27 -> 40279.479 | K27: 25 | L27: 21492.332 | M27: 12 | N27: =+M27*X27 -> 12101.966 | O27: 8 | P27: =+O27*AA27 -> 1839.6395 | Q27: 36 | R27: =+Q27*V27 -> 28455.354 | S27: =+G27+I27+K27+M27+O27+Q27 -> 376 | T27: =+H27+J27+L27+N27+P27+R27 -> 109394.36 | V27: =+V26 -> 790.42649 | W27: =+W24 -> 0 | X27: =+X24 -> 1008.4972 | Y27: =+Y24 -> 100.49203 | Z27: =+Z24 -> 165.75917 | AA27: =+AA24 -> 229.95494
A28: =+A27+1 -> 24 | C28: El Estor | E28: 0 | F28: 0 | G28: 30 | H28: =+G28*Y27 -> 3014.7609 | I28: 32 | J28: =+I28*Z28 -> 5304.2935 | K28: 4 | L28: 3438.7731 | M28: 9 | N28: =+M28*X28 -> 9076.4747 | O28: 6 | P28: =+O28*AA28 -> 1379.7296 | Q28: 86 | R28: =+Q28*V28 -> 67976.678 | S28: =+G28+I28+K28+M28+O28+Q28 -> 167 | T28: =+H28+J28+L28+N28+P28+R28 -> 90190.71 | V28: =+V27 -> 790.42649 | W28: =+W27 -> 0 | X28: =+X27 -> 1008.4972 | Y28: =+Y27 -> 100.49203 | Z28: =+Z27 -> 165.75917 | AA28: =+AA27 -> 229.95494
A29: =+A28+1 -> 25 | C29: Los Amates | E29: 0 | F29: 0 | G29: 23 | H29: =+G29*Y28 -> 2311.3167 | I29: 64 | J29: =+I29*Z29 -> 10608.587 | K29: 33 | L29: 28369.878 | M29: 0 | N29: =+M29*X29 -> 0 | O29: 125 | P29: =+O29*AA29 -> 28744.367 | Q29: 7 | R29: =+Q29*V29 -> 5532.9854 | S29: =+G29+I29+K29+M29+O29+Q29 -> 252 | T29: =+H29+J29+L29+N29+P29+R29 -> 75567.135 | V29: =+V28 -> 790.42649 | W29: =+W28 -> 0 | X29: =+X28 -> 1008.4972 | Y29: =+Y28 -> 100.49203 | Z29: =+Z28 -> 165.75917 | AA29: =+AA28 -> 229.95494
A30: =+A29+1 -> 26 | C30: Puerto Barrios | E30: 0 | F30: 0 | G30: 39 | H30: =+G30*Y29 -> 3919.1891 | I30: 39 | J30: =+I30*Z30 -> 6464.6077 | K30: 6 | L30: 5158.1597 | M30: 4 | N30: =+M30*X30 -> 4033.9888 | O30: 23 | P30: =+O30*AA30 -> 5288.9636 | Q30: 51 | R30: =+Q30*V30 -> 40311.751 | S30: =+G30+I30+K30+M30+O30+Q30 -> 162 | T30: =+H30+J30+L30+N30+P30+R30 -> 65176.66 | V30: =+V29 -> 790.42649 | W30: =+W29 -> 0 | X30: =+X29 -> 1008.4972 | Y30: =+Y29 -> 100.49203 | Z30: =+Z29 -> 165.75917 | AA30: =+AA29 -> 229.95494
A31: =+A30+1 -> 27 | C31: Morales | E31: 0 | F31: 0 | G31: 31 | H31: =+G31*Y30 -> 3115.2529 | I31: 45 | J31: =+I31*Z31 -> 7459.1627 | K31: 1 | L31: 859.69328 | M31: 3 | N31: =+M31*X31 -> 3025.4916 | O31: 27 | P31: =+O31*AA31 -> 6208.7833 | Q31: 15 | R31: =+Q31*V31 -> 11856.397 | S31: =+G31+I31+K31+M31+O31+Q31 -> 122 | T31: =+H31+J31+L31+N31+P31+R31 -> 32524.781 | V31: =+V30 -> 790.42649 | W31: =+W30 -> 0 | X31: =+X30 -> 1008.4972 | Y31: =+Y30 -> 100.49203 | Z31: =+Z30 -> 165.75917 | AA31: =+AA30 -> 229.95494
A32: =+A31+1 -> 28 | B32: Quetzaltenango | C32: Quetzaltenango | E32: 0 | F32: 0 | G32: 43 | H32: =+G32*Y31 -> 4321.1572 | I32: 160 | J32: =+I32*Z32 -> 26521.467 | K32: 43 | L32: 36966.811 | M32: 13 | N32: =+M32*X32 -> 13110.463 | O32: 346 | P32: =+O32*AA32 -> 79564.409 | Q32: 30 | R32: =+Q32*V32 -> 23712.795 | S32: =+G32+I32+K32+M32+O32+Q32 -> 635 | T32: =+H32+J32+L32+N32+P32+R32 -> 184197.1 | V32: =+V31 -> 790.42649 | W32: =+W31 -> 0 | X32: =+X31 -> 1008.4972 | Y32: =+Y31 -> 100.49203 | Z32: =+Z31 -> 165.75917 | AA32: =+AA31 -> 229.95494
A33: =+A32+1 -> 29 | C33: Cantel | E33: 0 | F33: 0 | G33: 43 | H33: =+G33*Y32 -> 4321.1572 | I33: 168 | J33: =+I33*Z33 -> 27847.541 | K33: 21 | L33: 18053.559 | M33: 10 | N33: =+M33*X33 -> 10084.972 | O33: 302 | P33: =+O33*AA33 -> 69446.391 | Q33: 41 | R33: =+Q33*V33 -> 32407.486 | S33: =+G33+I33+K33+M33+O33+Q33 -> 585 | T33: =+H33+J33+L33+N33+P33+R33 -> 162161.11 | V33: =+V32 -> 790.42649 | W33: =+W32 -> 0 | X33: =+X32 -> 1008.4972 | Y33: =+Y32 -> 100.49203 | Z33: =+Z32 -> 165.75917 | AA33: =+AA32 -> 229.95494
